Workbook

Sheet Legende
B2: Credit Comps — US Oil & Gas (20 Emittenten)
B3: Basisjahr FY2025 (31.12.2025) · Beträge USD Mio. · Quelle: SEC XBRL Companyfacts (10-K) · Stand 12.09.2026
B5: DATENHERKUNFT
B6: Sämtliche Finanzdaten stammen aus der SEC-XBRL-Schnittstelle (data.sec.gov/api/xbrl/companyfacts), also unmittelbar aus den geprüften 10-K-Abschlüssen zum 31.12.2025 — nicht aus Sekundärquellen. Jede Position ist im Sheet 'Input_Finanzen' bzw. 'Input_Adjustments' mit dem verwendeten XBRL-Tag belegt. Zwei Ausnahmen sind dort als 'manuell' gekennzeichnet (Capex ConocoPhillips und Phillips 66, die diese Position nur segmentdimensioniert taggen) sowie Reserven und Produktion, die in XBRL ausschließlich dimensional vorliegen und daher geschätzt sind.
B12: AGENTUR-ADJUSTIERTE VERSCHULDUNG — METHODIK
B13: Die veröffentlichten Kennzahlen von Moody's, S&P und Fitch sind proprietär. Das Sheet 'Agentur_Bruecke' repliziert stattdessen die jeweils VERÖFFENTLICHTE Adjustment-Methodik der drei Agenturen auf Basis der GAAP-Abschlüsse. Ergebnis ist eine nachvollziehbare Näherung, nicht die Agenturzahl selbst. Abweichungen entstehen vor allem durch: analystische Einzelfallurteile, vorausschauende bzw. Pro-forma-Betrachtungen, Preisdeck-Annahmen der Agenturen, JV-Quotenkonsolidierung und nicht-öffentliche Informationen. Erfahrungsgemäß liegt die Näherung innerhalb von etwa ±0,3x der publizierten Agenturkennzahl.
B19: Moody's — Financial Statement Adjustments | C19: Verschuldung = bilanzierte Finanzschulden + Operating-Leasing-Verbindlichkeit + Pensions-/OPEB-Nettoverbindlichkeit (nach Steuern) + Equity-Credit-Anteil der Hybride. BRUTTO-Betrachtung: Moody's rechnet Debt/EBITDA ohne Abzug liquider Mittel. AROs werden NICHT der Verschuldung zugerechnet, sondern im Geschäftsrisiko gewürdigt.
B20: S&P — Corporate Methodology: Ratios And Adjustments | C20: Verschuldung = bilanzierte Finanzschulden + Operating-Leasing + Pensions-/OPEB-Defizit (nach Steuern) + ASSET RETIREMENT OBLIGATIONS (nach Steuern) + Equity-Credit-Anteil der Hybride − anrechenbare liquide Mittel ('surplus cash', bei Investment Grade i.d.R. voll). Die ARO-Zurechnung ist der entscheidende Unterschied zu den beiden anderen Agenturen und trifft Upstream-Emittenten am stärksten.
B21: Fitch — Corporate Rating Criteria | C21: Leitkennzahl ist 'EBITDA Leverage' = Gesamtverschuldung mit Equity-Credit / Operating EBITDA, ebenfalls BRUTTO. Leasingverbindlichkeiten sind enthalten; AROs und Pensionsdefizite werden NICHT der Verschuldung zugerechnet. Ergänzend wird 'EBITDA Net Leverage' (nach Abzug liquider Mittel) ausgewiesen — beide Varianten stehen in der Brücke.
B22: Bereinigtes EBITDA (alle drei Agenturen) | C22: EBIT + Abschreibungen + Impairments/Sonderabschreibungen − Beteiligungsergebnis (Equity-Methode) + tatsächlich zugeflossene Ausschüttungen von Beteiligungen. Damit wird von nicht zahlungswirksamen Wertberichtigungen und von nicht ausgeschütteten Beteiligungserträgen bereinigt.
B24: WARUM DIE DREI WERTE AUSEINANDERLAUFEN
B25: Systematik | C25: S&P liegt bei Upstream-Emittenten typischerweise am höchsten (ARO-Zurechnung), Fitch am niedrigsten (keine ARO-/Pensionszurechnung), Moody's dazwischen. Bei Midstream und Services ist die Spanne gering, weil AROs und Pensionen dort kaum ins Gewicht fallen. Die Spalte 'Spanne' in der Brücke zeigt diesen Effekt je Emittent.
B27: FARBLEGENDE
B28: Blaue Schrift | C28: Hartkodierter Input aus dem Abschluss — hier editieren
B29: Schwarze Schrift | C29: Formel — nicht überschreiben
B30: Grüne Schrift | C30: Verweis auf ein anderes Sheet
B31: Gelbe Füllung | C31: In XBRL nicht als nicht-dimensionaler Wert vorhanden — ggf. manuell ergänzen
B33: KENNZAHLEN-DEFINITIONEN
B34: Net Debt / EBITDA | C34: (Finanzschulden − liquide Mittel) / EBITDA. Negativ = Netto-Cash-Position.
B35: Zinsdeckung EBITDA/Zins | C35: S&P-näherer Ansatz.
B36: Zinsdeckung EBIT/Zins | C36: Moody's-näherer Ansatz.
B37: FCF | C37: Operativer Cashflow − Capex, vor Ausschüttungen (= FOCF).
B38: FCF / Total Debt | C38: Agenturen rechnen überwiegend auf Bruttoverschuldung.
B39: Capex / D&A | C39: Investitionsintensität. <1,0x deutet auf Ernte-Modus bzw. Substanzverzehr.
B40: Payout / FCF | C40: (Dividenden + Rückkäufe) / FCF. >100% = Ausschüttung aus Bilanz oder Neuverschuldung.
B41: Fälligkeiten <24M | C41: Kurzfristige Finanzschulden (inkl. Commercial Paper) + Tilgungen Jahr 2 laut Schuldenspiegel.
B42: ROCE | C42: EBIT × (1 − effektive Steuerquote) / (Finanzschulden + Eigenkapital inkl. Minderheiten).
B43: Reserve Life (R/P) | C43: Nachgewiesene Reserven / Jahresproduktion. Nur Upstream.
B45: VERBLEIBENDE VORBEHALTE
B46: GAAP- vs. Agentur-EBITDA | C46: Über Impairments hinaus bereinigen die Agenturen weitere Sonderposten (Derivate-Bewertung, Veräußerungsgewinne, Restrukturierung). Diamondback zeigt den Effekt am deutlichsten: das GAAP-Betriebsergebnis 2025 ist durch hohe Wertberichtigungen belastet.
B47: JV-Quotenkonsolidierung | C47: Alle drei Agenturen rechnen bei Midstream teils anteilige JV-Schulden hinzu. Das ist aus dem Konzernabschluss nicht ableitbar und in der Brücke nicht abgebildet — Williams, ONEOK und Targa dürften dadurch real etwas höher liegen.
B48: Pensionsdefizit | C48: Verwendet wird die bilanzierte Nettoverbindlichkeit. Die Agenturen greifen auf den vollen Funded Status aus dem Pensionsanhang zu, der in XBRL nur dimensional vorliegt.
B49: Ratings | C49: Mit 'I' markierte Ratings sind gegen die Agenturseite bzw. den Abschnitt 'Credit Ratings' im aktuellen 10-Q zu verifizieren.

Sheet Input_Finanzen
A2: Input — Finanzdaten FY2025 (USD Mio.)
A3: Quelle: SEC XBRL Companyfacts, 10-K zum 31.12.2025. Graue Spalten sind Formeln.
A5: Ticker | B5: Unternehmen | C5: Sektor | D5: Qual. | E5: Langfr. Finanzschulden | F5: Kurzfr. Finanzschulden | G5: Gesamt- verschuldung | H5: Liquide Mittel | I5: Netto- verschuldung | J5: EBIT | K5: D&A | L5: EBITDA | M5: Zins- aufwand | N5: Operativer Cashflow | O5: Capex | P5: Free Cash Flow | Q5: Dividenden | R5: Aktien- rückkäufe | S5: Eigenkapital inkl. NCI | T5: Fällig <24M | U5: Eff. Steuer- quote | V5: Reserven (MMboe) | W5: Produktion (MMboe/a) | X5: Quelle / Hinweis zu ergänzten Werten
A6: XOM | B6: Exxon Mobil Corp. | C6: Integrated | D6: V | E6: 34241 | F6: 9296 | G6: =E6+F6 -> 43537 | H6: 10681 | I6: =G6-H6 -> 32856 | J6: 41871 | K6: 25993 | L6: =J6+K6 -> 67864 | M6: 603 | N6: 51970 | O6: 28358 | P6: =N6-O6 -> 23612 | Q6: 17231 | R6: 20273 | S6: 266626 | T6: 11796 | U6: 0.27876321 | V6: 16500 | W6: 1716 | X6: Res: Schaetzung; SEC-Reservetabelle nur dimensional | Prod: Schaetzung: ~4,7 MMboe/d x 365
A7: CVX | B7: Chevron Corp. | C7: Integrated | D7: V | E7: 39781 | F7: 10918 | G7: =E7+F7 -> 50699 | H7: 7285 | I7: =G7-H7 -> 43414 | J7: 20960 | K7: 20132 | L7: =J7+K7 -> 41092 | M7: 1217 | N7: 33939 | O7: 17347 | P7: =N7-O7 -> 16592 | Q7: 12751 | R7: 12079 | S7: 192176 | T7: 16641 | U7: 0.36762397 | V7: 10600 | W7: 1278 | X7: Res: 10-K FY2025: 10,6 Mrd. BOE zum 31.12.2025 | Prod: Schaetzung: ~3,5 MMboe/d x 365 (Hess ab Juli 2025)
A8: COP | B8: ConocoPhillips | C8: E&P | D8: V* | E8: 22424 | F8: 1020 | G8: =E8+F8 -> 23444 | H8: 6497 | I8: =G8-H8 -> 16947 | J8: 13832 | K8: 11500 | L8: =J8+K8 -> 25332 | M8: 1176 | N8: 19796 | O8: 12300 | P8: =N8-O8 -> 7496 | Q8: 3995 | R8: 5018 | S8: 64487 | T8: 1806 | U8: 0.36883692 | V8: 8000 | W8: 861 | X8: Res: Schaetzung; YE2024 laut 8-K 7,8 Mrd. BOE | Prod: Guidance FY2025 2,36 MMboed x 365
A9: EOG | B9: EOG Resources | C9: E&P | D9: V | E9: 7909 | F9: 27 | G9: =E9+F9 -> 7936 | H9: 3396 | I9: =G9-H9 -> 4540 | J9: 6385 | K9: 4461 | L9: =J9+K9 -> 10846 | M9: 235 | N9: 10044 | O9: 6115 | P9: =N9-O9 -> 3929 | Q9: 2161 | R9: 2564 | S9: 29833 | T9: 27 | U9: 0.21722729 | V9: 5514 | W9: 420 | X9: Res: 5.514 MMboe nach Encino-Akquisition | Prod: Schaetzung: ~1,15 MMboe/d x 365
A10: OXY | B10: Occidental Petroleum | C10: E&P | D10: V | E10: 20623 | F10: 1773 | G10: =E10+F10 -> 22396 | H10: 1968 | I10: =G10-H10 -> 20428 | J10: 4207 | K10: 7533 | L10: =J10+K10 -> 11740 | M10: 1079 | N10: 10532 | O10: 6427 | P10: =N10-O10 -> 4105 | Q10: 1594 | R10: 0 | S10: 36598 | T10: 1773 | U10: 0.32640665 | V10: 4600 | W10: 511 | X10: STD: LongTermDebtAndCapitalLeaseObligationsCurrent | Mat24: nur kurzfristiger Anteil; Jahr-2-Faelligkeiten nicht getaggt | Res: 10-K FY2025: 4,6 Mrd. BOE | Prod: 1,4 MMboe/d x 365
A11: FANG | B11: Diamondback Energy | C11: E&P | D11: V | E11: 13726 | F11: 763 | G11: =E11+F11 -> 14489 | H11: 104 | I11: =G11-H11 -> 14385 | J11: 1266 | K11: 5038 | L11: =J11+K11 -> 6304 | M11: 244 | N11: 8758 | O11: 3523 | P11: =N11-O11 -> 5235 | Q11: 1156 | R11: 2000 | S11: 42967 | T11: 2663 | U11: 0.17449306 | V11: 3618 | W11: 336 | X11: Res: ProvedDevelopedAndUndevelopedReserveNetEnergy (XBRL) | Prod: Schaetzung: ~0,92 MMboe/d x 365
A12: EXE | B12: Expand Energy | C12: E&P | D12: V | E12: 5009 | F12: 0 | G12: =E12+F12 -> 5009 | H12: 616 | I12: =G12-H12 -> 4393 | J12: 2471 | K12: 2980 | L12: =J12+K12 -> 5451 | M12: 235 | N12: 4575 | O12: 2736 | P12: =N12-O12 -> 1839 | Q12: 765 | R12: 100 | S12: 18578 | T12: 0 | U12: 0.2028922 | V12: 4313 | W12: 438 | X12: Mat24: Schuldenspiegel: keine Faelligkeiten in Jahr 1 und 2, erste in Jahr 3 | Res: 25.880 Bcfe (XBRL) / 6 | Prod: Schaetzung: ~7,2 Bcfe/d / 6 x 365
A13: EQT | B13: EQT Corp. | C13: E&P | D13: V | E13: 7293.2 | F13: 507.1 | G13: =E13+F13 -> 7800.3 | H13: 110.8 | I13: =G13-H13 -> 7689.5 | J13: 3249.6 | K13: 2600.4 | L13: =J13+K13 -> 5850 | M13: 438.7 | N13: 5126 | O13: 2288.4 | P13: =N13-O13 -> 2837.6 | Q13: 389.6 | R13: 0 | S13: 27360.1 | T13: 507.1 | U13: 0.2189336 | V13: 4674 | W13: 395 | X13: Res: 28.046 Bcfe (XBRL) / 6 | Prod: Schaetzung: ~6,5 Bcfe/d / 6 x 365
A14: DVN | B14: Devon Energy | C14: E&P | D14: V | E14: 7391 | F14: 998 | G14: =E14+F14 -> 8389 | H14: 1384 | I14: =G14-H14 -> 7005 | J14: 3963 | K14: 3595 | L14: =J14+K14 -> 7558 | M14: 497 | N14: 6711 | O14: 3592 | P14: =N14-O14 -> 3119 | Q14: 619 | R14: 1050 | S14: 15528 | T14: 1461 | U14: 0.22648586 | V14: 2400 | W14: 307 | X14: Res: 10-K FY2025: 2,4 Mrd. BOE | Prod: ~840 kboe/d x 365
A15: CTRA | B15: Coterra Energy | C15: E&P | D15: V | E15: 3568 | F15: 250 | G15: =E15+F15 -> 3818 | H15: 114 | I15: =G15-H15 -> 3704 | J15: 2452 | K15: 2370 | L15: =J15+K15 -> 4822 | M15: 205 | N15: 4021 | O15: 2288 | P15: =N15-O15 -> 1733 | Q15: 682 | R15: 141 | S15: 14838 | T15: 1000 | U15: 0.24127265 | V15: 3000 | W15: 281 | X15: Res: Schaetzung; YE2024 rund 2,9 Mrd. BOE | Prod: Schaetzung: ~0,77 MMboe/d x 365
A16: WMB | B16: Williams Companies | C16: Midstream | D16: V | E16: 27316 | F16: 1345 | G16: =E16+F16 -> 28661 | H16: 63 | I16: =G16-H16 -> 28598 | J16: 4196 | K16: 2347 | L16: =J16+K16 -> 6543 | M16: 1442 | N16: 5898 | O16: 4893 | P16: =N16-O16 -> 1005 | Q16: 2442 | R16: 0 | S16: 14995 | T16: 3339 | U16: 0.23641379 | V16: n/a | W16: n/a | X16: STD: LongTermDebtAndCapitalLeaseObligationsCurrent | Mat24: Faelligkeit Jahr 1 1.345 + Jahr 2 1.994
A17: KMI | B17: Kinder Morgan | C17: Midstream | D17: V | E17: 30777 | F17: 1226 | G17: =E17+F17 -> 32003 | H17: 63 | I17: =G17-H17 -> 31940 | J17: 4724 | K17: 2453 | L17: =J17+K17 -> 7177 | M17: 1801 | N17: 5917 | O17: 3026 | P17: =N17-O17 -> 2891 | Q17: 2604 | R17: 0 | S17: 32449 | T17: 2168 | U17: 0.20841683 | V17: n/a | W17: n/a
A18: OKE | B18: ONEOK | C18: Midstream | D18: V | E18: 30755 | F18: 1241 | G18: =E18+F18 -> 31996 | H18: 78 | I18: =G18-H18 -> 31918 | J18: 5741 | K18: 1514 | L18: =J18+K18 -> 7255 | M18: 1783 | N18: 5599 | O18: 3152 | P18: =N18-O18 -> 2447 | Q18: 2583 | R18: 75 | S18: 22569 | T18: 1241 | U18: 0.22895323 | V18: n/a | W18: n/a
A19: TRGP | B19: Targa Resources | C19: Midstream | D19: V | E19: 16662.4 | F19: 770 | G19: =E19+F19 -> 17432.4 | H19: 166.1 | I19: =G19-H19 -> 17266.3 | J19: 3331.2 | K19: 1515.3 | L19: =J19+K19 -> 4846.5 | M19: 852.8 | N19: 3917.4 | O19: 3333.3 | P19: =N19-O19 -> 584.1 | Q19: 815.1 | R19: 641.8 | S19: 3198.2 | T19: 1520 | U19: 0.21303893 | V19: n/a | W19: n/a | X19: STD: abgeleitet: LongTermDebt 17.432 abzueglich langfristigem Anteil 16.662 | Mat24: kurzfristiger Anteil 770 + Faelligkeit Jahr 2 750
A20: MPC | B20: Marathon Petroleum | C20: Refining | D20: V | E20: 30505 | F20: 2371 | G20: =E20+F20 -> 32876 | H20: 3672 | I20: =G20-H20 -> 29204 | J20: 8291 | K20: 3251 | L20: =J20+K20 -> 11542 | M20: 1489 | N20: 8253 | O20: 3486 | P20: =N20-O20 -> 4767 | Q20: 1140 | R20: 3488 | S20: 24086 | T20: 4385 | U20: 0.16208125 | V20: n/a | W20: n/a
A21: PSX | B21: Phillips 66 | C21: Refining | D21: V* | E21: 18678 | F21: 1038 | G21: =E21+F21 -> 19716 | H21: 1116 | I21: =G21-H21 -> 18600 | J21: 6417 | K21: 3251 | L21: =J21+K21 -> 9668 | M21: 997 | N21: 4962 | O21: 2200 | P21: =N21-O21 -> 2762 | Q21: 1922 | R21: 1207 | S21: 30241 | T21: 2320 | U21: 0.16457565 | V21: n/a | W21: n/a
A22: VLO | B22: Valero Energy | C22: Refining | D22: V | E22: 9670 | F22: 949 | G22: =E22+F22 -> 10619 | H22: 4688 | I22: =G22-H22 -> 5931 | J22: 3181 | K22: 3158 | L22: =J22+K22 -> 6339 | M22: 556 | N22: 5826 | O22: 1885 | P22: =N22-O22 -> 3941 | Q22: 1405 | R22: 2598 | S22: 26605 | T22: 1513 | U22: 0.25257903 | V22: n/a | W22: n/a
A23: SLB | B23: SLB (Schlumberger) | C23: Services | D23: V | E23: 9742 | F23: 1200 | G23: =E23+F23 -> 10942 | H23: 3036 | I23: =G23-H23 -> 7906 | J23: 4849 | K23: 2643 | L23: =J23+K23 -> 7492 | M23: 558 | N23: 6489 | O23: 1694 | P23: =N23-O23 -> 4795 | Q23: 1602 | R23: 2414 | S23: 27291 | T23: 2800 | U23: 0.19575856 | V23: n/a | W23: n/a | X23: STD: Schaetzung; kurzfristige Finanzschulden nicht separat getaggt | Mat24: geschaetzter kurzfristiger Anteil 1.200 + Faelligkeit Jahr 2 1.600
A24: BKR | B24: Baker Hughes | C24: Services | D24: V | E24: 5398 | F24: 689 | G24: =E24+F24 -> 6087 | H24: 3715 | I24: =G24-H24 -> 2372 | J24: 3099 | K24: 1188 | L24: =J24+K24 -> 4287 | M24: 222 | N24: 3810 | O24: 1273 | P24: =N24-O24 -> 2537 | Q24: 910 | R24: 384 | S24: 19010 | T24: 2076 | U24: 0.087938825 | V24: n/a | W24: n/a
A25: HAL | B25: Halliburton | C25: Services | D25: V | E25: 7158 | F25: 0 | G25: =E25+F25 -> 7158 | H25: 2206 | I25: =G25-H25 -> 4952 | J25: 2260 | K25: 1136 | L25: =J25+K25 -> 3396 | M25: 352 | N25: 2926 | O25: 1254 | P25: =N25-O25 -> 1672 | Q25: 579 | R25: 1007 | S25: 10505 | T25: 90 | U25: 0.27046866 | V25: n/a | W25: n/a
A27: Hinweise: | B27: 'V*' = Capex manuell aus dem Earnings Release ergänzt, weil ConocoPhillips und Phillips 66 diese Position in XBRL nur segmentdimensioniert taggen. Reserven und Produktion (V/W) sind Schätzungen — die SEC-Reservetabellen liegen in XBRL ebenfalls nur dimensional vor. Gelbe Zellen: kein nicht-dimensionaler XBRL-Wert vorhanden, bitte bei Bedarf aus dem 10-K ergänzen.

Sheet Input_Adjustments
A2: Input — Adjustment-Positionen FY2025 (USD Mio.)
A3: GAAP-Bilanz- und GuV-Posten, aus denen die Agentur-Adjustments abgeleitet werden.
A5: Ticker | B5: Unternehmen | C5: Sektor | D5: Operating-Leasing Verbindlichkeit | E5: Finanzierungs- leasing (Memo) | F5: Pensionen & OPEB (Nettoverbindlichkeit) | G5: Asset Retirement Obligations | H5: Hybride / Vorzugsaktien | I5: Beteiligungs- ergebnis | J5: Ausschüttungen v. Beteiligungen | K5: Impairments / Sonder-AfA | L5: Bereinigtes EBITDA
A6: XOM | B6: Exxon Mobil Corp. | C6: Integrated | D6: 6834 | E6: 2659 | F6: 8847 | G6: 12518 | H6: 0 | I6: 0 | J6: 3006 | K6: 0 | L6: =Input_Finanzen!L6+IF(K6="",0,K6)-IF(I6="",0,I6)+IF(J6="",0,J6) -> 70870 | M6: FL: FinanceLeaseLiability | Pref: keine Hybride/Vorzugsaktien | EqInc: netto ueber Ausschuettungen erfasst | DistAff: IncomeLossFromEquityMethodInvestmentsNetOfDividendsOrDistributions: Ausschuettungen uebersteigen Beteiligungsergebnis um 3.006 | Impair: keine wesentlichen Wertberichtigungen 2025
A7: CVX | B7: Chevron Corp. | C7: Integrated | D7: 5985 | E7: 1445 | F7: 4111 | G7: 14988 | H7: 0 | I7: 3000 | J7: 5282 | K7: 133 | L7: =Input_Finanzen!L7+IF(K7="",0,K7)-IF(I7="",0,I7)+IF(J7="",0,J7) -> 43507 | M7: Pref: keine Hybride/Vorzugsaktien
A8: COP | B8: ConocoPhillips | C8: E&P | D8: 950 | E8: 904 | F8: 969 | G8: 8364 | H8: 0 | I8: 1335 | J8: 1531 | K8: 26 | L8: =Input_Finanzen!L8+IF(K8="",0,K8)-IF(I8="",0,I8)+IF(J8="",0,J8) -> 25554 | M8: FL: FinanceLeaseLiabilityPaymentsDue (undiskontiert) | Pref: keine Hybride/Vorzugsaktien
A9: EOG | B9: EOG Resources | C9: E&P | D9: 1199 | E9: 117 | F9: 0 | G9: 1570 | H9: 0 | I9: 0 | J9: 0 | K9: 843 | L9: =Input_Finanzen!L9+IF(K9="",0,K9)-IF(I9="",0,I9)+IF(J9="",0,J9) -> 11689 | M9: Pens: keine leistungsorientierten Plaene | Pref: keine Hybride/Vorzugsaktien | EqInc: keine wesentlichen Equity-Beteiligungen | DistAff: keine wesentlichen Equity-Beteiligungen
A10: OXY | B10: Occidental Petroleum | C10: E&P | D10: 955 | E10: 999 | F10: 985 | G10: 4553 | H10: 8287 | I10: 76 | J10: 705 | K10: 109 | L10: =Input_Finanzen!L10+IF(K10="",0,K10)-IF(I10="",0,I10)+IF(J10="",0,J10) -> 12478 | M10: Pens: PensionAndOtherPostretirementAndPostemploymentBenefitPlansLiabilitiesNoncurrent | Impair: ExplorationAbandonmentAndImpairmentExpense
A11: FANG | B11: Diamondback Energy | C11: E&P | D11: 0 | E11: 0 | F11: 0 | G11: 542 | H11: 0 | I11: 0 | J11: 0 | K11: 3652 | L11: =Input_Finanzen!L11+IF(K11="",0,K11)-IF(I11="",0,I11)+IF(J11="",0,J11) -> 9956 | M11: FL: kein wesentliches Finanzierungsleasing | Pens: keine leistungsorientierten Plaene | Pref: keine Hybride/Vorzugsaktien | EqInc: keine wesentlichen Equity-Beteiligungen | DistAff: keine wesentlichen Equity-Beteiligungen
A12: EXE | B12: Expand Energy | C12: E&P | D12: 99 | E12: 0 | F12: 0 | G12: 724 | H12: 0 | I12: 0 | J12: 0 | K12: 37 | L12: =Input_Finanzen!L12+IF(K12="",0,K12)-IF(I12="",0,I12)+IF(J12="",0,J12) -> 5488 | M12: FL: kein wesentliches Finanzierungsleasing | Pens: keine leistungsorientierten Plaene | Pref: keine Hybride/Vorzugsaktien | EqInc: keine wesentlichen Equity-Beteiligungen | DistAff: keine wesentlichen Equity-Beteiligungen
A13: EQT | B13: EQT Corp. | C13: E&P | D13: 78.4 | E13: 37.1 | F13: 0 | G13: 1019.5 | H13: 0 | I13: 0 | J13: 257.2 | K13: 51.2 | L13: =Input_Finanzen!L13+IF(K13="",0,K13)-IF(I13="",0,I13)+IF(J13="",0,J13) -> 6158.4 | M13: Pens: keine leistungsorientierten Plaene | Pref: keine Hybride/Vorzugsaktien | EqInc: Ausschuettungen separat erfasst
A14: DVN | B14: Devon Energy | C14: E&P | D14: 276 | E14: 23 | F14: 169 | G14: 906 | H14: 0 | I14: 0 | J14: 0 | K14: 254 | L14: =Input_Finanzen!L14+IF(K14="",0,K14)-IF(I14="",0,I14)+IF(J14="",0,J14) -> 7812 | M14: Pens: PBO 613 abzueglich Planvermoegen 444 | Pref: keine Hybride/Vorzugsaktien | EqInc: keine wesentlichen Equity-Beteiligungen | DistAff: keine wesentlichen Equity-Beteiligungen
A15: CTRA | B15: Coterra Energy | C15: E&P | D15: 188 | E15: 0 | F15: 10 | G15: 343 | H15: 8 | I15: 0 | J15: 0 | K15: 0 | L15: =Input_Finanzen!L15+IF(K15="",0,K15)-IF(I15="",0,I15)+IF(J15="",0,J15) -> 4822 | M15: FL: kein wesentliches Finanzierungsleasing | EqInc: keine wesentlichen Equity-Beteiligungen | DistAff: keine wesentlichen Equity-Beteiligungen | Impair: keine wesentlichen Wertberichtigungen 2025
A16: WMB | B16: Williams Companies | C16: Midstream | D16: 183 | E16: 0 | F16: 0 | G16: 2587 | H16: 35 | I16: 760 | J16: 800 | K16: 212 | L16: =Input_Finanzen!L16+IF(K16="",0,K16)-IF(I16="",0,I16)+IF(J16="",0,J16) -> 6795 | M16: FL: im Schuldenausweis enthalten, nicht separat getaggt | Pens: keine wesentliche Nettoverbindlichkeit | Impair: OtherAssetImpairmentCharges
A17: KMI | B17: Kinder Morgan | C17: Midstream | D17: 216 | E17: 0 | F17: 0 | G17: 255 | H17: 0 | I17: 896 | J17: 805 | K17: 6 | L17: =Input_Finanzen!L17+IF(K17="",0,K17)-IF(I17="",0,I17)+IF(J17="",0,J17) -> 7092 | M17: FL: kein wesentliches Finanzierungsleasing | Pens: keine wesentliche Nettoverbindlichkeit | Pref: keine Hybride/Vorzugsaktien | Impair: GainLossOnSalesOfAssetsAndAssetImpairmentCharges
... A25: HAL | B25: Halliburton | C25: Services | D25: 975 | E25: 183 | F25: 0 | G25: 0 | H25: 0 | I25: -50 | J25: 0 | K25: 0 | L25: =Input_Finanzen!L25+IF(K25="",0,K25)-IF(I25="",0,I25)+IF(J25="",0,J25) -> 3446 | M25: Pens: keine wesentliche Nettoverbindlichkeit | ARO: keine wesentliche Position | Pref: keine Hybride/Vorzugsaktien | DistAff: keine wesentlichen Equity-Beteiligungen
A27: Hinweise: | B27: Finanzierungsleasing (E) ist nachrichtlich — es ist nach ASC 842 bereits in den bilanzierten Finanzschulden enthalten und wird deshalb in der Brücke NICHT erneut addiert. Leere Felder bei ARO, Pensionen und Hybriden bedeuten in aller Regel, dass die Position beim jeweiligen Emittenten nicht besteht oder unwesentlich ist (z. B. keine nennenswerten AROs bei Ölfeldservices). Bereinigtes EBITDA (L) = EBITDA + Impairments − Beteiligungsergebnis + Ausschüttungen.

Sheet Input_Ratings
A2: Input — Ratings
A3: Stand September 2026. 'n.r.' = von dieser Agentur nicht öffentlich geratet.
A5: Ticker | B5: Unternehmen | C5: Sektor | D5: Qual. | E5: Moody's | F5: Outlook | G5: S&P | H5: Outlook | I5: Fitch | J5: Outlook | K5: Bemerkung
A6: XOM | B6: Exxon Mobil Corp. | C6: Integrated | D6: V | E6: Aa2 | F6: stable | G6: AA- | H6: positive | I6: n.r. | K6: S&P Ausblick Juni 2026 auf positiv angehoben
A7: CVX | B7: Chevron Corp. | C7: Integrated | D7: V | E7: Aa2 | F7: stable | G7: AA- | H7: stable | I7: n.r.
A8: COP | B8: ConocoPhillips | C8: E&P | D8: V | E8: A2 | F8: stable | G8: A- | H8: stable | I8: A | J8: stable | K8: Ratings laut 10-Q Q3/2025 bestätigt
A9: EOG | B9: EOG Resources | C9: E&P | D9: I | E9: A2 | F9: stable | G9: A | H9: stable | I9: n.r. | K9: kein öffentliches Fitch-Rating recherchierbar — zu prüfen
A10: OXY | B10: Occidental Petroleum | C10: E&P | D10: I | E10: Baa3 | F10: stable | G10: BBB- | H10: positive | I10: BBB- | J10: stable
A11: FANG | B11: Diamondback Energy | C11: E&P | D11: I | E11: Baa3 | F11: positive | G11: BBB | H11: stable | I11: BBB | J11: stable | K11: Moody's-Upgrade auf Baa3 im April 2025
A12: EXE | B12: Expand Energy | C12: E&P | D12: V | E12: Baa3 | F12: stable | G12: BBB- | H12: stable | I12: BBB- | J12: stable
A13: EQT | B13: EQT Corp. | C13: E&P | D13: I | E13: Baa3 | F13: positive | G13: BBB- | H13: positive | I13: BBB- | J13: positive
A14: DVN | B14: Devon Energy | C14: E&P | D14: I | E14: Baa3 | F14: stable | G14: BBB- | H14: stable | I14: BBB | J14: stable
A15: CTRA | B15: Coterra Energy | C15: E&P | D15: I | E15: Baa2 | F15: stable | G15: BBB | H15: stable | I15: BBB | J15: stable
A16: WMB | B16: Williams Companies | C16: Midstream | D16: I | E16: Baa2 | F16: stable | G16: BBB | H16: stable | I16: BBB | J16: stable
A17: KMI | B17: Kinder Morgan | C17: Midstream | D17: V | E17: Baa1 | F17: stable | G17: BBB+ | H17: stable | I17: BBB+ | J17: stable | K17: Moody's-Upgrade auf Baa1 im Q1 2026
A18: OKE | B18: ONEOK | C18: Midstream | D18: I | E18: Baa2 | F18: stable | G18: BBB | H18: stable | I18: BBB | J18: stable
A19: TRGP | B19: Targa Resources | C19: Midstream | D19: I | E19: Baa3 | F19: positive | G19: BBB | H19: stable | I19: BBB- | J19: positive
A20: MPC | B20: Marathon Petroleum | C20: Refining | D20: I | E20: Baa2 | F20: stable | G20: BBB | H20: stable | I20: BBB | J20: stable
A21: PSX | B21: Phillips 66 | C21: Refining | D21: I | E21: Baa1 | F21: stable | G21: BBB+ | H21: stable | I21: BBB+ | J21: stable
A22: VLO | B22: Valero Energy | C22: Refining | D22: I | E22: Baa2 | F22: stable | G22: BBB | H22: stable | I22: BBB | J22: stable
A23: SLB | B23: SLB (Schlumberger) | C23: Services | D23: I | E23: A3 | F23: stable | G23: A- | H23: stable | I23: n.r. | K23: kein öffentliches Fitch-Rating recherchierbar — zu prüfen
A24: BKR | B24: Baker Hughes | C24: Services | D24: I | E24: Baa1 | F24: stable | G24: BBB+ | H24: stable | I24: n.r. | K24: kein öffentliches Fitch-Rating recherchierbar — zu prüfen
A25: HAL | B25: Halliburton | C25: Services | D25: I | E25: Baa2 | F25: stable | G25: BBB+ | H25: positive | I25: n.r. | K25: kein öffentliches Fitch-Rating recherchierbar — zu prüfen

Sheet Agentur_Bruecke
A2: Agentur-adjustierte Verschuldung — Replikation der veröffentlichten Methodiken
A3: Näherung auf Basis der GAAP-Abschlüsse, nicht die publizierte Agenturkennzahl. Methodik siehe Sheet 'Legende'.
A4: Annahmen: | C4: Steuersatz Adjustments | E4: 0.25 | F4: Equity-Credit Hybride | H4: 0.5 | I4: Cash-Anrechnung S&P | K4: 1
F5: MOODY'S | K5: S&P GLOBAL RATINGS | R5: FITCH RATINGS | W5: VERGLEICH
A6: Ticker | B6: Unternehmen | C6: Sektor | D6: Finanz- schulden | E6: Bereinigtes EBITDA | F6: + Operating- Leasing | G6: + Pensionen (n. Steuern) | H6: + Hybride × EC | I6: Moody's Adj. Debt | J6: Moody's Adj. Debt/EBITDA | K6: + Operating- Leasing | L6: + Pensionen (n. Steuern) | M6: + ARO (n. Steuern) | N6: + Hybride × EC | O6: − Liquide Mittel | P6: S&P Adj. Debt | Q6: S&P Adj. Debt/EBITDA | R6: + Leasing | S6: + Hybride × EC | T6: Fitch Adj. Debt (brutto) | U6: Fitch EBITDA Leverage | V6: Fitch EBITDA Net Leverage | W6: Reported Net Debt/EBITDA | X6: Spanne (max−min)
A7: XOM | B7: =Input_Finanzen!B6 -> Exxon Mobil Corp. | C7: Integrated | D7: =Input_Finanzen!G6 -> 43537 | E7: =Input_Adjustments!L6 -> 70870 | F7: =IF(Input_Adjustments!D6="",0,Input_Adjustments!D6) -> 6834 | G7: =IF(Input_Adjustments!F6="",0,Input_Adjustments!F6)*(1-$E$4) -> 6635.25 | H7: =IF(Input_Adjustments!H6="",0,Input_Adjustments!H6)*$H$4 -> 0 | I7: =D7+F7+G7+H7 -> 57006.25 | J7: =IFERROR(I7/E7,"n/a") -> 0.80437773 | K7: =IF(Input_Adjustments!D6="",0,Input_Adjustments!D6) -> 6834 | L7: =IF(Input_Adjustments!F6="",0,Input_Adjustments!F6)*(1-$E$4) -> 6635.25 | M7: =IF(Input_Adjustments!G6="",0,Input_Adjustments!G6)*(1-$E$4) -> 9388.5 | N7: =IF(Input_Adjustments!H6="",0,Input_Adjustments!H6)*$H$4 -> 0 | O7: =-Input_Finanzen!H6*$K$4 -> -10681 | P7: =D7+K7+L7+M7+N7+O7 -> 55713.75 | Q7: =IFERROR(P7/E7,"n/a") -> 0.78614012 | R7: =IF(Input_Adjustments!D6="",0,Input_Adjustments!D6) -> 6834 | S7: =IF(Input_Adjustments!H6="",0,Input_Adjustments!H6)*$H$4 -> 0 | T7: =D7+R7+S7 -> 50371 | U7: =IFERROR(T7/E7,"n/a") -> 0.71075208 | V7: =IFERROR((T7-Input_Finanzen!H6)/E7,"n/a") -> 0.56003951 | W7: =IFERROR(Input_Finanzen!I6/Input_Finanzen!L6,"n/a") -> 0.48414476 | X7: =IFERROR(MAX(J7,Q7,U7)-MIN(J7,Q7,U7),"n/a") -> 0.093625653
A8: CVX | B8: =Input_Finanzen!B7 -> Chevron Corp. | C8: Integrated | D8: =Input_Finanzen!G7 -> 50699 | E8: =Input_Adjustments!L7 -> 43507 | F8: =IF(Input_Adjustments!D7="",0,Input_Adjustments!D7) -> 5985 | G8: =IF(Input_Adjustments!F7="",0,Input_Adjustments!F7)*(1-$E$4) -> 3083.25 | H8: =IF(Input_Adjustments!H7="",0,Input_Adjustments!H7)*$H$4 -> 0 | I8: =D8+F8+G8+H8 -> 59767.25 | J8: =IFERROR(I8/E8,"n/a") -> 1.3737387 | K8: =IF(Input_Adjustments!D7="",0,Input_Adjustments!D7) -> 5985 | L8: =IF(Input_Adjustments!F7="",0,Input_Adjustments!F7)*(1-$E$4) -> 3083.25 | M8: =IF(Input_Adjustments!G7="",0,Input_Adjustments!G7)*(1-$E$4) -> 11241 | N8: =IF(Input_Adjustments!H7="",0,Input_Adjustments!H7)*$H$4 -> 0 | O8: =-Input_Finanzen!H7*$K$4 -> -7285 | P8: =D8+K8+L8+M8+N8+O8 -> 63723.25 | Q8: =IFERROR(P8/E8,"n/a") -> 1.4646666 | R8: =IF(Input_Adjustments!D7="",0,Input_Adjustments!D7) -> 5985 | S8: =IF(Input_Adjustments!H7="",0,Input_Adjustments!H7)*$H$4 -> 0 | T8: =D8+R8+S8 -> 56684 | U8: =IFERROR(T8/E8,"n/a") -> 1.3028708 | V8: =IFERROR((T8-Input_Finanzen!H7)/E8,"n/a") -> 1.1354265 | W8: =IFERROR(Input_Finanzen!I7/Input_Finanzen!L7,"n/a") -> 1.0565073 | X8: =IFERROR(MAX(J8,Q8,U8)-MIN(J8,Q8,U8),"n/a") -> 0.1617958
A9: COP | B9: =Input_Finanzen!B8 -> ConocoPhillips | C9: E&P | D9: =Input_Finanzen!G8 -> 23444 | E9: =Input_Adjustments!L8 -> 25554 | F9: =IF(Input_Adjustments!D8="",0,Input_Adjustments!D8) -> 950 | G9: =IF(Input_Adjustments!F8="",0,Input_Adjustments!F8)*(1-$E$4) -> 726.75 | H9: =IF(Input_Adjustments!H8="",0,Input_Adjustments!H8)*$H$4 -> 0 | I9: =D9+F9+G9+H9 -> 25120.75 | J9: =IFERROR(I9/E9,"n/a") -> 0.98304571 | K9: =IF(Input_Adjustments!D8="",0,Input_Adjustments!D8) -> 950 | L9: =IF(Input_Adjustments!F8="",0,Input_Adjustments!F8)*(1-$E$4) -> 726.75 | M9: =IF(Input_Adjustments!G8="",0,Input_Adjustments!G8)*(1-$E$4) -> 6273 | N9: =IF(Input_Adjustments!H8="",0,Input_Adjustments!H8)*$H$4 -> 0 | O9: =-Input_Finanzen!H8*$K$4 -> -6497 | P9: =D9+K9+L9+M9+N9+O9 -> 24896.75 | Q9: =IFERROR(P9/E9,"n/a") -> 0.97427996 | R9: =IF(Input_Adjustments!D8="",0,Input_Adjustments!D8) -> 950 | S9: =IF(Input_Adjustments!H8="",0,Input_Adjustments!H8)*$H$4 -> 0 | T9: =D9+R9+S9 -> 24394 | U9: =IFERROR(T9/E9,"n/a") -> 0.95460593 | V9: =IFERROR((T9-Input_Finanzen!H8)/E9,"n/a") -> 0.70036002 | W9: =IFERROR(Input_Finanzen!I8/Input_Finanzen!L8,"n/a") -> 0.66899574 | X9: =IFERROR(MAX(J9,Q9,U9)-MIN(J9,Q9,U9),"n/a") -> 0.028439775
A10: EOG | B10: =Input_Finanzen!B9 -> EOG Resources | C10: E&P | D10: =Input_Finanzen!G9 -> 7936 | E10: =Input_Adjustments!L9 -> 11689 | F10: =IF(Input_Adjustments!D9="",0,Input_Adjustments!D9) -> 1199 | G10: =IF(Input_Adjustments!F9="",0,Input_Adjustments!F9)*(1-$E$4) -> 0 | H10: =IF(Input_Adjustments!H9="",0,Input_Adjustments!H9)*$H$4 -> 0 | I10: =D10+F10+G10+H10 -> 9135 | J10: =IFERROR(I10/E10,"n/a") -> 0.78150398 | K10: =IF(Input_Adjustments!D9="",0,Input_Adjustments!D9) -> 1199 | L10: =IF(Input_Adjustments!F9="",0,Input_Adjustments!F9)*(1-$E$4) -> 0 | M10: =IF(Input_Adjustments!G9="",0,Input_Adjustments!G9)*(1-$E$4) -> 1177.5 | N10: =IF(Input_Adjustments!H9="",0,Input_Adjustments!H9)*$H$4 -> 0 | O10: =-Input_Finanzen!H9*$K$4 -> -3396 | P10: =D10+K10+L10+M10+N10+O10 -> 6916.5 | Q10: =IFERROR(P10/E10,"n/a") -> 0.59171015 | R10: =IF(Input_Adjustments!D9="",0,Input_Adjustments!D9) -> 1199 | S10: =IF(Input_Adjustments!H9="",0,Input_Adjustments!H9)*$H$4 -> 0 | T10: =D10+R10+S10 -> 9135 | U10: =IFERROR(T10/E10,"n/a") -> 0.78150398 | V10: =IFERROR((T10-Input_Finanzen!H9)/E10,"n/a") -> 0.49097442 | W10: =IFERROR(Input_Finanzen!I9/Input_Finanzen!L9,"n/a") -> 0.4185875 | X10: =IFERROR(MAX(J10,Q10,U10)-MIN(J10,Q10,U10),"n/a") -> 0.18979382
A11: OXY | B11: =Input_Finanzen!B10 -> Occidental Petroleum | C11: E&P | D11: =Input_Finanzen!G10 -> 22396 | E11: =Input_Adjustments!L10 -> 12478 | F11: =IF(Input_Adjustments!D10="",0,Input_Adjustments!D10) -> 955 | G11: =IF(Input_Adjustments!F10="",0,Input_Adjustments!F10)*(1-$E$4) -> 738.75 | H11: =IF(Input_Adjustments!H10="",0,Input_Adjustments!H10)*$H$4 -> 4143.5 | I11: =D11+F11+G11+H11 -> 28233.25 | J11: =IFERROR(I11/E11,"n/a") -> 2.2626423 | K11: =IF(Input_Adjustments!D10="",0,Input_Adjustments!D10) -> 955 | L11: =IF(Input_Adjustments!F10="",0,Input_Adjustments!F10)*(1-$E$4) -> 738.75 | M11: =IF(Input_Adjustments!G10="",0,Input_Adjustments!G10)*(1-$E$4) -> 3414.75 | N11: =IF(Input_Adjustments!H10="",0,Input_Adjustments!H10)*$H$4 -> 4143.5 | O11: =-Input_Finanzen!H10*$K$4 -> -1968 | P11: =D11+K11+L11+M11+N11+O11 -> 29680 | Q11: =IFERROR(P11/E11,"n/a") -> 2.3785863 | R11: =IF(Input_Adjustments!D10="",0,Input_Adjustments!D10) -> 955 | S11: =IF(Input_Adjustments!H10="",0,Input_Adjustments!H10)*$H$4 -> 4143.5 | T11: =D11+R11+S11 -> 27494.5 | U11: =IFERROR(T11/E11,"n/a") -> 2.2034381 | V11: =IFERROR((T11-Input_Finanzen!H10)/E11,"n/a") -> 2.0457205 | W11: =IFERROR(Input_Finanzen!I10/Input_Finanzen!L10,"n/a") -> 1.7400341 | X11: =IFERROR(MAX(J11,Q11,U11)-MIN(J11,Q11,U11),"n/a") -> 0.17514826
A12: FANG | B12: =Input_Finanzen!B11 -> Diamondback Energy | C12: E&P | D12: =Input_Finanzen!G11 -> 14489 | E12: =Input_Adjustments!L11 -> 9956 | F12: =IF(Input_Adjustments!D11="",0,Input_Adjustments!D11) -> 0 | G12: =IF(Input_Adjustments!F11="",0,Input_Adjustments!F11)*(1-$E$4) -> 0 | H12: =IF(Input_Adjustments!H11="",0,Input_Adjustments!H11)*$H$4 -> 0 | I12: =D12+F12+G12+H12 -> 14489 | J12: =IFERROR(I12/E12,"n/a") -> 1.4553033 | K12: =IF(Input_Adjustments!D11="",0,Input_Adjustments!D11) -> 0 | L12: =IF(Input_Adjustments!F11="",0,Input_Adjustments!F11)*(1-$E$4) -> 0 | M12: =IF(Input_Adjustments!G11="",0,Input_Adjustments!G11)*(1-$E$4) -> 406.5 | N12: =IF(Input_Adjustments!H11="",0,Input_Adjustments!H11)*$H$4 -> 0 | O12: =-Input_Finanzen!H11*$K$4 -> -104 | P12: =D12+K12+L12+M12+N12+O12 -> 14791.5 | Q12: =IFERROR(P12/E12,"n/a") -> 1.485687 | R12: =IF(Input_Adjustments!D11="",0,Input_Adjustments!D11) -> 0 | S12: =IF(Input_Adjustments!H11="",0,Input_Adjustments!H11)*$H$4 -> 0 | T12: =D12+R12+S12 -> 14489 | U12: =IFERROR(T12/E12,"n/a") -> 1.4553033 | V12: =IFERROR((T12-Input_Finanzen!H11)/E12,"n/a") -> 1.4448574 | W12: =IFERROR(Input_Finanzen!I11/Input_Finanzen!L11,"n/a") -> 2.2818845 | X12: =IFERROR(MAX(J12,Q12,U12)-MIN(J12,Q12,U12),"n/a") -> 0.030383688
A13: EXE | B13: =Input_Finanzen!B12 -> Expand Energy | C13: E&P | D13: =Input_Finanzen!G12 -> 5009 | E13: =Input_Adjustments!L12 -> 5488 | F13: =IF(Input_Adjustments!D12="",0,Input_Adjustments!D12) -> 99 | G13: =IF(Input_Adjustments!F12="",0,Input_Adjustments!F12)*(1-$E$4) -> 0 | H13: =IF(Input_Adjustments!H12="",0,Input_Adjustments!H12)*$H$4 -> 0 | I13: =D13+F13+G13+H13 -> 5108 | J13: =IFERROR(I13/E13,"n/a") -> 0.93075802 | K13: =IF(Input_Adjustments!D12="",0,Input_Adjustments!D12) -> 99 | L13: =IF(Input_Adjustments!F12="",0,Input_Adjustments!F12)*(1-$E$4) -> 0 | M13: =IF(Input_Adjustments!G12="",0,Input_Adjustments!G12)*(1-$E$4) -> 543 | N13: =IF(Input_Adjustments!H12="",0,Input_Adjustments!H12)*$H$4 -> 0 | O13: =-Input_Finanzen!H12*$K$4 -> -616 | P13: =D13+K13+L13+M13+N13+O13 -> 5035 | Q13: =IFERROR(P13/E13,"n/a") -> 0.91745627 | R13: =IF(Input_Adjustments!D12="",0,Input_Adjustments!D12) -> 99 | S13: =IF(Input_Adjustments!H12="",0,Input_Adjustments!H12)*$H$4 -> 0 | T13: =D13+R13+S13 -> 5108 | U13: =IFERROR(T13/E13,"n/a") -> 0.93075802 | V13: =IFERROR((T13-Input_Finanzen!H12)/E13,"n/a") -> 0.81851312 | W13: =IFERROR(Input_Finanzen!I12/Input_Finanzen!L12,"n/a") -> 0.80590717 | X13: =IFERROR(MAX(J13,Q13,U13)-MIN(J13,Q13,U13),"n/a") -> 0.013301749
A14: EQT | B14: =Input_Finanzen!B13 -> EQT Corp. | C14: E&P | D14: =Input_Finanzen!G13 -> 7800.3 | E14: =Input_Adjustments!L13 -> 6158.4 | F14: =IF(Input_Adjustments!D13="",0,Input_Adjustments!D13) -> 78.4 | G14: =IF(Input_Adjustments!F13="",0,Input_Adjustments!F13)*(1-$E$4) -> 0 | H14: =IF(Input_Adjustments!H13="",0,Input_Adjustments!H13)*$H$4 -> 0 | I14: =D14+F14+G14+H14 -> 7878.7 | J14: =IFERROR(I14/E14,"n/a") -> 1.279342 | K14: =IF(Input_Adjustments!D13="",0,Input_Adjustments!D13) -> 78.4 | L14: =IF(Input_Adjustments!F13="",0,Input_Adjustments!F13)*(1-$E$4) -> 0 | M14: =IF(Input_Adjustments!G13="",0,Input_Adjustments!G13)*(1-$E$4) -> 764.625 | N14: =IF(Input_Adjustments!H13="",0,Input_Adjustments!H13)*$H$4 -> 0 | O14: =-Input_Finanzen!H13*$K$4 -> -110.8 | P14: =D14+K14+L14+M14+N14+O14 -> 8532.525 | Q14: =IFERROR(P14/E14,"n/a") -> 1.38551 | R14: =IF(Input_Adjustments!D13="",0,Input_Adjustments!D13) -> 78.4 | S14: =IF(Input_Adjustments!H13="",0,Input_Adjustments!H13)*$H$4 -> 0 | T14: =D14+R14+S14 -> 7878.7 | U14: =IFERROR(T14/E14,"n/a") -> 1.279342 | V14: =IFERROR((T14-Input_Finanzen!H13)/E14,"n/a") -> 1.2613504 | W14: =IFERROR(Input_Finanzen!I13/Input_Finanzen!L13,"n/a") -> 1.3144444 | X14: =IFERROR(MAX(J14,Q14,U14)-MIN(J14,Q14,U14),"n/a") -> 0.106168
A15: DVN | B15: =Input_Finanzen!B14 -> Devon Energy | C15: E&P | D15: =Input_Finanzen!G14 -> 8389 | E15: =Input_Adjustments!L14 -> 7812 | F15: =IF(Input_Adjustments!D14="",0,Input_Adjustments!D14) -> 276 | G15: =IF(Input_Adjustments!F14="",0,Input_Adjustments!F14)*(1-$E$4) -> 126.75 | H15: =IF(Input_Adjustments!H14="",0,Input_Adjustments!H14)*$H$4 -> 0 | I15: =D15+F15+G15+H15 -> 8791.75 | J15: =IFERROR(I15/E15,"n/a") -> 1.125416 | K15: =IF(Input_Adjustments!D14="",0,Input_Adjustments!D14) -> 276 | L15: =IF(Input_Adjustments!F14="",0,Input_Adjustments!F14)*(1-$E$4) -> 126.75 | M15: =IF(Input_Adjustments!G14="",0,Input_Adjustments!G14)*(1-$E$4) -> 679.5 | N15: =IF(Input_Adjustments!H14="",0,Input_Adjustments!H14)*$H$4 -> 0 | O15: =-Input_Finanzen!H14*$K$4 -> -1384 | P15: =D15+K15+L15+M15+N15+O15 -> 8087.25 | Q15: =IFERROR(P15/E15,"n/a") -> 1.0352343 | R15: =IF(Input_Adjustments!D14="",0,Input_Adjustments!D14) -> 276 | S15: =IF(Input_Adjustments!H14="",0,Input_Adjustments!H14)*$H$4 -> 0 | T15: =D15+R15+S15 -> 8665 | U15: =IFERROR(T15/E15,"n/a") -> 1.109191 | V15: =IFERROR((T15-Input_Finanzen!H14)/E15,"n/a") -> 0.93202765 | W15: =IFERROR(Input_Finanzen!I14/Input_Finanzen!L14,"n/a") -> 0.9268325 | X15: =IFERROR(MAX(J15,Q15,U15)-MIN(J15,Q15,U15),"n/a") -> 0.090181772
A16: CTRA | B16: =Input_Finanzen!B15 -> Coterra Energy | C16: E&P | D16: =Input_Finanzen!G15 -> 3818 | E16: =Input_Adjustments!L15 -> 4822 | F16: =IF(Input_Adjustments!D15="",0,Input_Adjustments!D15) -> 188 | G16: =IF(Input_Adjustments!F15="",0,Input_Adjustments!F15)*(1-$E$4) -> 7.5 | H16: =IF(Input_Adjustments!H15="",0,Input_Adjustments!H15)*$H$4 -> 4 | I16: =D16+F16+G16+H16 -> 4017.5 | J16: =IFERROR(I16/E16,"n/a") -> 0.83316051 | K16: =IF(Input_Adjustments!D15="",0,Input_Adjustments!D15) -> 188 | L16: =IF(Input_Adjustments!F15="",0,Input_Adjustments!F15)*(1-$E$4) -> 7.5 | M16: =IF(Input_Adjustments!G15="",0,Input_Adjustments!G15)*(1-$E$4) -> 257.25 | N16: =IF(Input_Adjustments!H15="",0,Input_Adjustments!H15)*$H$4 -> 4 | O16: =-Input_Finanzen!H15*$K$4 -> -114 | P16: =D16+K16+L16+M16+N16+O16 -> 4160.75 | Q16: =IFERROR(P16/E16,"n/a") -> 0.8628681 | R16: =IF(Input_Adjustments!D15="",0,Input_Adjustments!D15) -> 188 | S16: =IF(Input_Adjustments!H15="",0,Input_Adjustments!H15)*$H$4 -> 4 | T16: =D16+R16+S16 -> 4010 | U16: =IFERROR(T16/E16,"n/a") -> 0.83160514 | V16: =IFERROR((T16-Input_Finanzen!H15)/E16,"n/a") -> 0.8079635 | W16: =IFERROR(Input_Finanzen!I15/Input_Finanzen!L15,"n/a") -> 0.768146 | X16: =IFERROR(MAX(J16,Q16,U16)-MIN(J16,Q16,U16),"n/a") -> 0.031262961
A17: WMB | B17: =Input_Finanzen!B16 -> Williams Companies | C17: Midstream | D17: =Input_Finanzen!G16 -> 28661 | E17: =Input_Adjustments!L16 -> 6795 | F17: =IF(Input_Adjustments!D16="",0,Input_Adjustments!D16) -> 183 | G17: =IF(Input_Adjustments!F16="",0,Input_Adjustments!F16)*(1-$E$4) -> 0 | H17: =IF(Input_Adjustments!H16="",0,Input_Adjustments!H16)*$H$4 -> 17.5 | I17: =D17+F17+G17+H17 -> 28861.5 | J17: =IFERROR(I17/E17,"n/a") -> 4.2474614 | K17: =IF(Input_Adjustments!D16="",0,Input_Adjustments!D16) -> 183 | L17: =IF(Input_Adjustments!F16="",0,Input_Adjustments!F16)*(1-$E$4) -> 0 | M17: =IF(Input_Adjustments!G16="",0,Input_Adjustments!G16)*(1-$E$4) -> 1940.25 | N17: =IF(Input_Adjustments!H16="",0,Input_Adjustments!H16)*$H$4 -> 17.5 | O17: =-Input_Finanzen!H16*$K$4 -> -63 | P17: =D17+K17+L17+M17+N17+O17 -> 30738.75 | Q17: =IFERROR(P17/E17,"n/a") -> 4.5237307 | R17: =IF(Input_Adjustments!D16="",0,Input_Adjustments!D16) -> 183 | S17: =IF(Input_Adjustments!H16="",0,Input_Adjustments!H16)*$H$4 -> 17.5 | T17: =D17+R17+S17 -> 28861.5 | U17: =IFERROR(T17/E17,"n/a") -> 4.2474614 | V17: =IFERROR((T17-Input_Finanzen!H16)/E17,"n/a") -> 4.2381898 | W17: =IFERROR(Input_Finanzen!I16/Input_Finanzen!L16,"n/a") -> 4.3707779 | X17: =IFERROR(MAX(J17,Q17,U17)-MIN(J17,Q17,U17),"n/a") -> 0.27626932
A18: KMI | B18: =Input_Finanzen!B17 -> Kinder Morgan | C18: Midstream | D18: =Input_Finanzen!G17 -> 32003 | E18: =Input_Adjustments!L17 -> 7092 | F18: =IF(Input_Adjustments!D17="",0,Input_Adjustments!D17) -> 216 | G18: =IF(Input_Adjustments!F17="",0,Input_Adjustments!F17)*(1-$E$4) -> 0 | H18: =IF(Input_Adjustments!H17="",0,Input_Adjustments!H17)*$H$4 -> 0 | I18: =D18+F18+G18+H18 -> 32219 | J18: =IFERROR(I18/E18,"n/a") -> 4.5430062 | K18: =IF(Input_Adjustments!D17="",0,Input_Adjustments!D17) -> 216 | L18: =IF(Input_Adjustments!F17="",0,Input_Adjustments!F17)*(1-$E$4) -> 0 | M18: =IF(Input_Adjustments!G17="",0,Input_Adjustments!G17)*(1-$E$4) -> 191.25 | N18: =IF(Input_Adjustments!H17="",0,Input_Adjustments!H17)*$H$4 -> 0 | O18: =-Input_Finanzen!H17*$K$4 -> -63 | P18: =D18+K18+L18+M18+N18+O18 -> 32347.25 | Q18: =IFERROR(P18/E18,"n/a") -> 4.56109 | R18: =IF(Input_Adjustments!D17="",0,Input_Adjustments!D17) -> 216 | S18: =IF(Input_Adjustments!H17="",0,Input_Adjustments!H17)*$H$4 -> 0 | T18: =D18+R18+S18 -> 32219 | U18: =IFERROR(T18/E18,"n/a") -> 4.5430062 | V18: =IFERROR((T18-Input_Finanzen!H17)/E18,"n/a") -> 4.534123 | W18: =IFERROR(Input_Finanzen!I17/Input_Finanzen!L17,"n/a") -> 4.4503274 | X18: =IFERROR(MAX(J18,Q18,U18)-MIN(J18,Q18,U18),"n/a") -> 0.018083756
... A26: HAL | B26: =Input_Finanzen!B25 -> Halliburton | C26: Services | D26: =Input_Finanzen!G25 -> 7158 | E26: =Input_Adjustments!L25 -> 3446 | F26: =IF(Input_Adjustments!D25="",0,Input_Adjustments!D25) -> 975 | G26: =IF(Input_Adjustments!F25="",0,Input_Adjustments!F25)*(1-$E$4) -> 0 | H26: =IF(Input_Adjustments!H25="",0,Input_Adjustments!H25)*$H$4 -> 0 | I26: =D26+F26+G26+H26 -> 8133 | J26: =IFERROR(I26/E26,"n/a") -> 2.3601277 | K26: =IF(Input_Adjustments!D25="",0,Input_Adjustments!D25) -> 975 | L26: =IF(Input_Adjustments!F25="",0,Input_Adjustments!F25)*(1-$E$4) -> 0 | M26: =IF(Input_Adjustments!G25="",0,Input_Adjustments!G25)*(1-$E$4) -> 0 | N26: =IF(Input_Adjustments!H25="",0,Input_Adjustments!H25)*$H$4 -> 0 | O26: =-Input_Finanzen!H25*$K$4 -> -2206 | P26: =D26+K26+L26+M26+N26+O26 -> 5927 | Q26: =IFERROR(P26/E26,"n/a") -> 1.7199652 | R26: =IF(Input_Adjustments!D25="",0,Input_Adjustments!D25) -> 975 | S26: =IF(Input_Adjustments!H25="",0,Input_Adjustments!H25)*$H$4 -> 0 | T26: =D26+R26+S26 -> 8133 | U26: =IFERROR(T26/E26,"n/a") -> 2.3601277 | V26: =IFERROR((T26-Input_Finanzen!H25)/E26,"n/a") -> 1.7199652 | W26: =IFERROR(Input_Finanzen!I25/Input_Finanzen!L25,"n/a") -> 1.4581861 | X26: =IFERROR(MAX(J26,Q26,U26)-MIN(J26,Q26,U26),"n/a") -> 0.64016251
A28: MEDIAN | B28: Gesamtsample (20) | D28: =IFERROR(MEDIAN(D7:D26),"n/a") -> 15960.7 | E28: =IFERROR(MEDIAN(E7:E26),"n/a") -> 7617 | F28: =IFERROR(MEDIAN(F7:F26),"n/a") -> 760 | G28: =IFERROR(MEDIAN(G7:G26),"n/a") -> 67.125 | H28: =IFERROR(MEDIAN(H7:H26),"n/a") -> 0 | I28: =IFERROR(MEDIAN(I7:I26),"n/a") -> 16017.6 | J28: =IFERROR(MEDIAN(J7:J26),"n/a") -> 1.5906483 | K28: =IFERROR(MEDIAN(K7:K26),"n/a") -> 760 | ... X28: =IFERROR(MEDIAN(X7:X26),"n/a") -> 0.099896825
A29: MEDIAN | B29: Integrated (2) | D29: =IFERROR(MEDIAN(D7:D8),"n/a") -> 47118 | E29: =IFERROR(MEDIAN(E7:E8),"n/a") -> 57188.5 | F29: =IFERROR(MEDIAN(F7:F8),"n/a") -> 6409.5 | G29: =IFERROR(MEDIAN(G7:G8),"n/a") -> 4859.25 | H29: =IFERROR(MEDIAN(H7:H8),"n/a") -> 0 | I29: =IFERROR(MEDIAN(I7:I8),"n/a") -> 58386.75 | J29: =IFERROR(MEDIAN(J7:J8),"n/a") -> 1.0890582 | K29: =IFERROR(MEDIAN(K7:K8),"n/a") -> 6409.5 | ... X29: =IFERROR(MEDIAN(X7:X8),"n/a") -> 0.12771073
A30: MEDIAN | B30: E&P (8) | D30: =IFERROR(MEDIAN(D9:D16),"n/a") -> 8162.5 | E30: =IFERROR(MEDIAN(E9:E16),"n/a") -> 8884 | F30: =IFERROR(MEDIAN(F9:F16),"n/a") -> 232 | G30: =IFERROR(MEDIAN(G9:G16),"n/a") -> 3.75 | H30: =IFERROR(MEDIAN(H9:H16),"n/a") -> 0 | I30: =IFERROR(MEDIAN(I9:I16),"n/a") -> 8963.375 | J30: =IFERROR(MEDIAN(J9:J16),"n/a") -> 1.0542309 | K30: =IFERROR(MEDIAN(K9:K16),"n/a") -> 232 | ... X30: =IFERROR(MEDIAN(X9:X16),"n/a") -> 0.060722367
A31: MEDIAN | B31: Midstream (4) | D31: =IFERROR(MEDIAN(D17:D20),"n/a") -> 30328.5 | E31: =IFERROR(MEDIAN(E17:E20),"n/a") -> 6943.5 | F31: =IFERROR(MEDIAN(F17:F20),"n/a") -> 199.5 | G31: =IFERROR(MEDIAN(G17:G20),"n/a") -> 0 | H31: =IFERROR(MEDIAN(H17:H20),"n/a") -> 0 | I31: =IFERROR(MEDIAN(I17:I20),"n/a") -> 30540.25 | J31: =IFERROR(MEDIAN(J17:J20),"n/a") -> 4.3418011 | K31: =IFERROR(MEDIAN(K17:K20),"n/a") -> 199.5 | ... X31: =IFERROR(MEDIAN(X17:X20),"n/a") -> 0.014409343
A32: MEDIAN | B32: Refining (3) | D32: =IFERROR(MEDIAN(D21:D23),"n/a") -> 19716 | E32: =IFERROR(MEDIAN(E21:E23),"n/a") -> 10056 | F32: =IFERROR(MEDIAN(F21:F23),"n/a") -> 1482 | G32: =IFERROR(MEDIAN(G21:G23),"n/a") -> 429.75 | H32: =IFERROR(MEDIAN(H21:H23),"n/a") -> 0 | I32: =IFERROR(MEDIAN(I21:I23),"n/a") -> 22015.75 | J32: =IFERROR(MEDIAN(J21:J23),"n/a") -> 2.1893148 | K32: =IFERROR(MEDIAN(K21:K23),"n/a") -> 1482 | ... X32: =IFERROR(MEDIAN(X21:X23),"n/a") -> 0.31100671
A33: MEDIAN | B33: Services (3) | D33: =IFERROR(MEDIAN(D24:D26),"n/a") -> 7158 | E33: =IFERROR(MEDIAN(E24:E26),"n/a") -> 4309 | F33: =IFERROR(MEDIAN(F24:F26),"n/a") -> 905 | G33: =IFERROR(MEDIAN(G24:G26),"n/a") -> 359.25 | H33: =IFERROR(MEDIAN(H24:H26),"n/a") -> 0 | I33: =IFERROR(MEDIAN(I24:I26),"n/a") -> 8133 | J33: =IFERROR(MEDIAN(J24:J26),"n/a") -> 1.7408912 | K33: =IFERROR(MEDIAN(K24:K26),"n/a") -> 905 | ... X33: =IFERROR(MEDIAN(X24:X26),"n/a") -> 0.64016251
A35: Lesehilfe: | B35: Moody's und Fitch rechnen auf Bruttoverschuldung, S&P zieht anrechenbare liquide Mittel ab — die S&P-Kennzahl ist deshalb nicht per se die konservativste, obwohl sie als einzige AROs zurechnet. Bei Emittenten mit hoher Kassenhaltung (Baker Hughes, Valero, EOG) dreht sich das Bild entsprechend. Die Spalte 'Spanne' zeigt, wie stark die drei Methodiken beim jeweiligen Emittenten auseinanderlaufen: hohe Werte signalisieren, dass die Ratingeinschätzung stark von der Behandlung von AROs und Kasse abhängt.

Sheet Kennzahlen
A2: Kennzahlen-Übersicht — Credit Comps US Oil & Gas, FY2025
A3: Vollständig formelbasiert. Spalten R:T sind Näherungen der Agentur-Methodiken aus dem Sheet 'Agentur_Bruecke'.
A5: Ticker | B5: Unternehmen | C5: Sektor | D5: Net Debt / EBITDA | E5: Zinsdeckung EBITDA/Zins | F5: Zinsdeckung EBIT/Zins | G5: Free Cash Flow ($m) | H5: FCF / Net Debt | I5: FCF / Total Debt | J5: Capex / D&A | K5: Payout ($m) | L5: Payout / FCF | M5: Fällig <24M ($m) | N5: <24M / Total Debt | O5: Moody's | P5: S&P | Q5: Fitch | R5: Moody's adj. Debt/EBITDA | S5: S&P adj. Debt/EBITDA | T5: Fitch adj. Debt/EBITDA | U5: ROCE | V5: Reserve Life (Jahre)
A6: XOM | B6: =Input_Finanzen!B6 -> Exxon Mobil Corp. | C6: Integrated | D6: =IFERROR(Input_Finanzen!I6/Input_Finanzen!L6,"n/a") -> 0.48414476 | E6: =IFERROR(Input_Finanzen!L6/Input_Finanzen!M6,"n/a") -> 112.54395 | F6: =IFERROR(Input_Finanzen!J6/Input_Finanzen!M6,"n/a") -> 69.437811 | G6: =IFERROR(Input_Finanzen!P6,"n/a") -> 23612 | H6: =IF(Input_Finanzen!I6<=0,"n.m.",IFERROR(Input_Finanzen!P6/Input_Finanzen!I6,"n/a")) -> 0.71865108 | I6: =IFERROR(Input_Finanzen!P6/Input_Finanzen!G6,"n/a") -> 0.54234329 | J6: =IFERROR(Input_Finanzen!O6/Input_Finanzen!K6,"n/a") -> 1.090986 | K6: =IFERROR(IF(Input_Finanzen!Q6="",0,Input_Finanzen!Q6)+IF(Input_Finanzen!R6="",0,Input_Finanzen!R6),"n/a") -> 37504 | L6: =IF(Input_Finanzen!P6<=0,"n.m.",IFERROR(K6/Input_Finanzen!P6,"n/a")) -> 1.5883449 | M6: =IF(Input_Finanzen!T6="","n/v",Input_Finanzen!T6) -> 11796 | N6: =IF(Input_Finanzen!T6="","n/v",IFERROR(Input_Finanzen!T6/Input_Finanzen!G6,"n/a")) -> 0.27094196 | O6: =IF(Input_Ratings!E6="","n/v",Input_Ratings!E6&" ("&Input_Ratings!F6&")") -> Aa2 (stable) | P6: =IF(Input_Ratings!G6="","n/v",Input_Ratings!G6&" ("&Input_Ratings!H6&")") -> AA- (positive) | Q6: =IF(Input_Ratings!I6="","n/v",Input_Ratings!I6&IF(Input_Ratings!J6=""," "," ("&Input_Ratings!J6&")")) -> n.r. | R6: =Agentur_Bruecke!J7 -> 0.80437773 | S6: =Agentur_Bruecke!Q7 -> 0.78614012 | T6: =Agentur_Bruecke!U7 -> 0.71075208 | U6: =IFERROR(Input_Finanzen!J6*(1-Input_Finanzen!U6)/(Input_Finanzen!G6+Input_Finanzen!S6),"n/a") -> 0.09736463 | V6: =IF(OR(Input_Finanzen!V6="",Input_Finanzen!W6=""),"n/v",IFERROR(Input_Finanzen!V6/Input_Finanzen!W6,"n/a")) -> 9.6153846
A7: CVX | B7: =Input_Finanzen!B7 -> Chevron Corp. | C7: Integrated | D7: =IFERROR(Input_Finanzen!I7/Input_Finanzen!L7,"n/a") -> 1.0565073 | E7: =IFERROR(Input_Finanzen!L7/Input_Finanzen!M7,"n/a") -> 33.764996 | F7: =IFERROR(Input_Finanzen!J7/Input_Finanzen!M7,"n/a") -> 17.222679 | G7: =IFERROR(Input_Finanzen!P7,"n/a") -> 16592 | H7: =IF(Input_Finanzen!I7<=0,"n.m.",IFERROR(Input_Finanzen!P7/Input_Finanzen!I7,"n/a")) -> 0.38218086 | I7: =IFERROR(Input_Finanzen!P7/Input_Finanzen!G7,"n/a") -> 0.32726484 | J7: =IFERROR(Input_Finanzen!O7/Input_Finanzen!K7,"n/a") -> 0.86166302 | K7: =IFERROR(IF(Input_Finanzen!Q7="",0,Input_Finanzen!Q7)+IF(Input_Finanzen!R7="",0,Input_Finanzen!R7),"n/a") -> 24830 | L7: =IF(Input_Finanzen!P7<=0,"n.m.",IFERROR(K7/Input_Finanzen!P7,"n/a")) -> 1.4965043 | M7: =IF(Input_Finanzen!T7="","n/v",Input_Finanzen!T7) -> 16641 | N7: =IF(Input_Finanzen!T7="","n/v",IFERROR(Input_Finanzen!T7/Input_Finanzen!G7,"n/a")) -> 0.32823133 | O7: =IF(Input_Ratings!E7="","n/v",Input_Ratings!E7&" ("&Input_Ratings!F7&")") -> Aa2 (stable) | P7: =IF(Input_Ratings!G7="","n/v",Input_Ratings!G7&" ("&Input_Ratings!H7&")") -> AA- (stable) | Q7: =IF(Input_Ratings!I7="","n/v",Input_Ratings!I7&IF(Input_Ratings!J7=""," "," ("&Input_Ratings!J7&")")) -> n.r. | R7: =Agentur_Bruecke!J8 -> 1.3737387 | S7: =Agentur_Bruecke!Q8 -> 1.4646666 | T7: =Agentur_Bruecke!U8 -> 1.3028708 | U7: =IFERROR(Input_Finanzen!J7*(1-Input_Finanzen!U7)/(Input_Finanzen!G7+Input_Finanzen!S7),"n/a") -> 0.054573759 | V7: =IF(OR(Input_Finanzen!V7="",Input_Finanzen!W7=""),"n/v",IFERROR(Input_Finanzen!V7/Input_Finanzen!W7,"n/a")) -> 8.2942097
A8: COP | B8: =Input_Finanzen!B8 -> ConocoPhillips | C8: E&P | D8: =IFERROR(Input_Finanzen!I8/Input_Finanzen!L8,"n/a") -> 0.66899574 | E8: =IFERROR(Input_Finanzen!L8/Input_Finanzen!M8,"n/a") -> 21.540816 | F8: =IFERROR(Input_Finanzen!J8/Input_Finanzen!M8,"n/a") -> 11.761905 | G8: =IFERROR(Input_Finanzen!P8,"n/a") -> 7496 | H8: =IF(Input_Finanzen!I8<=0,"n.m.",IFERROR(Input_Finanzen!P8/Input_Finanzen!I8,"n/a")) -> 0.44232017 | I8: =IFERROR(Input_Finanzen!P8/Input_Finanzen!G8,"n/a") -> 0.31974066 | J8: =IFERROR(Input_Finanzen!O8/Input_Finanzen!K8,"n/a") -> 1.0695652 | K8: =IFERROR(IF(Input_Finanzen!Q8="",0,Input_Finanzen!Q8)+IF(Input_Finanzen!R8="",0,Input_Finanzen!R8),"n/a") -> 9013 | L8: =IF(Input_Finanzen!P8<=0,"n.m.",IFERROR(K8/Input_Finanzen!P8,"n/a")) -> 1.2023746 | M8: =IF(Input_Finanzen!T8="","n/v",Input_Finanzen!T8) -> 1806 | N8: =IF(Input_Finanzen!T8="","n/v",IFERROR(Input_Finanzen!T8/Input_Finanzen!G8,"n/a")) -> 0.077034636 | O8: =IF(Input_Ratings!E8="","n/v",Input_Ratings!E8&" ("&Input_Ratings!F8&")") -> A2 (stable) | P8: =IF(Input_Ratings!G8="","n/v",Input_Ratings!G8&" ("&Input_Ratings!H8&")") -> A- (stable) | Q8: =IF(Input_Ratings!I8="","n/v",Input_Ratings!I8&IF(Input_Ratings!J8=""," "," ("&Input_Ratings!J8&")")) -> A (stable) | R8: =Agentur_Bruecke!J9 -> 0.98304571 | S8: =Agentur_Bruecke!Q9 -> 0.97427996 | T8: =Agentur_Bruecke!U9 -> 0.95460593 | U8: =IFERROR(Input_Finanzen!J8*(1-Input_Finanzen!U8)/(Input_Finanzen!G8+Input_Finanzen!S8),"n/a") -> 0.09928521 | V8: =IF(OR(Input_Finanzen!V8="",Input_Finanzen!W8=""),"n/v",IFERROR(Input_Finanzen!V8/Input_Finanzen!W8,"n/a")) -> 9.2915215
A9: EOG | B9: =Input_Finanzen!B9 -> EOG Resources | C9: E&P | D9: =IFERROR(Input_Finanzen!I9/Input_Finanzen!L9,"n/a") -> 0.4185875 | E9: =IFERROR(Input_Finanzen!L9/Input_Finanzen!M9,"n/a") -> 46.153191 | F9: =IFERROR(Input_Finanzen!J9/Input_Finanzen!M9,"n/a") -> 27.170213 | G9: =IFERROR(Input_Finanzen!P9,"n/a") -> 3929 | H9: =IF(Input_Finanzen!I9<=0,"n.m.",IFERROR(Input_Finanzen!P9/Input_Finanzen!I9,"n/a")) -> 0.8654185 | I9: =IFERROR(Input_Finanzen!P9/Input_Finanzen!G9,"n/a") -> 0.49508569 | J9: =IFERROR(Input_Finanzen!O9/Input_Finanzen!K9,"n/a") -> 1.3707689 | K9: =IFERROR(IF(Input_Finanzen!Q9="",0,Input_Finanzen!Q9)+IF(Input_Finanzen!R9="",0,Input_Finanzen!R9),"n/a") -> 4725 | L9: =IF(Input_Finanzen!P9<=0,"n.m.",IFERROR(K9/Input_Finanzen!P9,"n/a")) -> 1.2025961 | M9: =IF(Input_Finanzen!T9="","n/v",Input_Finanzen!T9) -> 27 | N9: =IF(Input_Finanzen!T9="","n/v",IFERROR(Input_Finanzen!T9/Input_Finanzen!G9,"n/a")) -> 0.0034022177 | O9: =IF(Input_Ratings!E9="","n/v",Input_Ratings!E9&" ("&Input_Ratings!F9&")") -> A2 (stable) | P9: =IF(Input_Ratings!G9="","n/v",Input_Ratings!G9&" ("&Input_Ratings!H9&")") -> A (stable) | Q9: =IF(Input_Ratings!I9="","n/v",Input_Ratings!I9&IF(Input_Ratings!J9=""," "," ("&Input_Ratings!J9&")")) -> n.r. | R9: =Agentur_Bruecke!J10 -> 0.78150398 | S9: =Agentur_Bruecke!Q10 -> 0.59171015 | T9: =Agentur_Bruecke!U10 -> 0.78150398 | U9: =IFERROR(Input_Finanzen!J9*(1-Input_Finanzen!U9)/(Input_Finanzen!G9+Input_Finanzen!S9),"n/a") -> 0.13233085 | V9: =IF(OR(Input_Finanzen!V9="",Input_Finanzen!W9=""),"n/v",IFERROR(Input_Finanzen!V9/Input_Finanzen!W9,"n/a")) -> 13.128571
A10: OXY | B10: =Input_Finanzen!B10 -> Occidental Petroleum | C10: E&P | D10: =IFERROR(Input_Finanzen!I10/Input_Finanzen!L10,"n/a") -> 1.7400341 | E10: =IFERROR(Input_Finanzen!L10/Input_Finanzen!M10,"n/a") -> 10.880445 | F10: =IFERROR(Input_Finanzen!J10/Input_Finanzen!M10,"n/a") -> 3.8989805 | G10: =IFERROR(Input_Finanzen!P10,"n/a") -> 4105 | H10: =IF(Input_Finanzen!I10<=0,"n.m.",IFERROR(Input_Finanzen!P10/Input_Finanzen!I10,"n/a")) -> 0.20094968 | I10: =IFERROR(Input_Finanzen!P10/Input_Finanzen!G10,"n/a") -> 0.18329166 | J10: =IFERROR(Input_Finanzen!O10/Input_Finanzen!K10,"n/a") -> 0.85317934 | K10: =IFERROR(IF(Input_Finanzen!Q10="",0,Input_Finanzen!Q10)+IF(Input_Finanzen!R10="",0,Input_Finanzen!R10),"n/a") -> 1594 | L10: =IF(Input_Finanzen!P10<=0,"n.m.",IFERROR(K10/Input_Finanzen!P10,"n/a")) -> 0.38830694 | M10: =IF(Input_Finanzen!T10="","n/v",Input_Finanzen!T10) -> 1773 | N10: =IF(Input_Finanzen!T10="","n/v",IFERROR(Input_Finanzen!T10/Input_Finanzen!G10,"n/a")) -> 0.079165922 | O10: =IF(Input_Ratings!E10="","n/v",Input_Ratings!E10&" ("&Input_Ratings!F10&")") -> Baa3 (stable) | P10: =IF(Input_Ratings!G10="","n/v",Input_Ratings!G10&" ("&Input_Ratings!H10&")") -> BBB- (positive) | Q10: =IF(Input_Ratings!I10="","n/v",Input_Ratings!I10&IF(Input_Ratings!J10=""," "," ("&Input_Ratings!J10&")")) -> BBB- (stable) | R10: =Agentur_Bruecke!J11 -> 2.2626423 | S10: =Agentur_Bruecke!Q11 -> 2.3785863 | T10: =Agentur_Bruecke!U11 -> 2.2034381 | U10: =IFERROR(Input_Finanzen!J10*(1-Input_Finanzen!U10)/(Input_Finanzen!G10+Input_Finanzen!S10),"n/a") -> 0.048035516 | V10: =IF(OR(Input_Finanzen!V10="",Input_Finanzen!W10=""),"n/v",IFERROR(Input_Finanzen!V10/Input_Finanzen!W10,"n/a")) -> 9.0019569
A11: FANG | B11: =Input_Finanzen!B11 -> Diamondback Energy | C11: E&P | D11: =IFERROR(Input_Finanzen!I11/Input_Finanzen!L11,"n/a") -> 2.2818845 | E11: =IFERROR(Input_Finanzen!L11/Input_Finanzen!M11,"n/a") -> 25.836066 | F11: =IFERROR(Input_Finanzen!J11/Input_Finanzen!M11,"n/a") -> 5.1885246 | G11: =IFERROR(Input_Finanzen!P11,"n/a") -> 5235 | H11: =IF(Input_Finanzen!I11<=0,"n.m.",IFERROR(Input_Finanzen!P11/Input_Finanzen!I11,"n/a")) -> 0.36392075 | I11: =IFERROR(Input_Finanzen!P11/Input_Finanzen!G11,"n/a") -> 0.36130858 | J11: =IFERROR(Input_Finanzen!O11/Input_Finanzen!K11,"n/a") -> 0.69928543 | K11: =IFERROR(IF(Input_Finanzen!Q11="",0,Input_Finanzen!Q11)+IF(Input_Finanzen!R11="",0,Input_Finanzen!R11),"n/a") -> 3156 | L11: =IF(Input_Finanzen!P11<=0,"n.m.",IFERROR(K11/Input_Finanzen!P11,"n/a")) -> 0.60286533 | M11: =IF(Input_Finanzen!T11="","n/v",Input_Finanzen!T11) -> 2663 | N11: =IF(Input_Finanzen!T11="","n/v",IFERROR(Input_Finanzen!T11/Input_Finanzen!G11,"n/a")) -> 0.1837946 | O11: =IF(Input_Ratings!E11="","n/v",Input_Ratings!E11&" ("&Input_Ratings!F11&")") -> Baa3 (positive) | P11: =IF(Input_Ratings!G11="","n/v",Input_Ratings!G11&" ("&Input_Ratings!H11&")") -> BBB (stable) | Q11: =IF(Input_Ratings!I11="","n/v",Input_Ratings!I11&IF(Input_Ratings!J11=""," "," ("&Input_Ratings!J11&")")) -> BBB (stable) | R11: =Agentur_Bruecke!J12 -> 1.4553033 | S11: =Agentur_Bruecke!Q12 -> 1.485687 | T11: =Agentur_Bruecke!U12 -> 1.4553033 | U11: =IFERROR(Input_Finanzen!J11*(1-Input_Finanzen!U11)/(Input_Finanzen!G11+Input_Finanzen!S11),"n/a") -> 0.018189428 | V11: =IF(OR(Input_Finanzen!V11="",Input_Finanzen!W11=""),"n/v",IFERROR(Input_Finanzen!V11/Input_Finanzen!W11,"n/a")) -> 10.767857
A12: EXE | B12: =Input_Finanzen!B12 -> Expand Energy | C12: E&P | D12: =IFERROR(Input_Finanzen!I12/Input_Finanzen!L12,"n/a") -> 0.80590717 | E12: =IFERROR(Input_Finanzen!L12/Input_Finanzen!M12,"n/a") -> 23.195745 | F12: =IFERROR(Input_Finanzen!J12/Input_Finanzen!M12,"n/a") -> 10.514894 | G12: =IFERROR(Input_Finanzen!P12,"n/a") -> 1839 | H12: =IF(Input_Finanzen!I12<=0,"n.m.",IFERROR(Input_Finanzen!P12/Input_Finanzen!I12,"n/a")) -> 0.41862053 | I12: =IFERROR(Input_Finanzen!P12/Input_Finanzen!G12,"n/a") -> 0.36713915 | J12: =IFERROR(Input_Finanzen!O12/Input_Finanzen!K12,"n/a") -> 0.91812081 | K12: =IFERROR(IF(Input_Finanzen!Q12="",0,Input_Finanzen!Q12)+IF(Input_Finanzen!R12="",0,Input_Finanzen!R12),"n/a") -> 865 | L12: =IF(Input_Finanzen!P12<=0,"n.m.",IFERROR(K12/Input_Finanzen!P12,"n/a")) -> 0.47036433 | M12: =IF(Input_Finanzen!T12="","n/v",Input_Finanzen!T12) -> 0 | N12: =IF(Input_Finanzen!T12="","n/v",IFERROR(Input_Finanzen!T12/Input_Finanzen!G12,"n/a")) -> 0 | O12: =IF(Input_Ratings!E12="","n/v",Input_Ratings!E12&" ("&Input_Ratings!F12&")") -> Baa3 (stable) | P12: =IF(Input_Ratings!G12="","n/v",Input_Ratings!G12&" ("&Input_Ratings!H12&")") -> BBB- (stable) | Q12: =IF(Input_Ratings!I12="","n/v",Input_Ratings!I12&IF(Input_Ratings!J12=""," "," ("&Input_Ratings!J12&")")) -> BBB- (stable) | R12: =Agentur_Bruecke!J13 -> 0.93075802 | S12: =Agentur_Bruecke!Q13 -> 0.91745627 | T12: =Agentur_Bruecke!U13 -> 0.93075802 | U12: =IFERROR(Input_Finanzen!J12*(1-Input_Finanzen!U12)/(Input_Finanzen!G12+Input_Finanzen!S12),"n/a") -> 0.083505888 | V12: =IF(OR(Input_Finanzen!V12="",Input_Finanzen!W12=""),"n/v",IFERROR(Input_Finanzen!V12/Input_Finanzen!W12,"n/a")) -> 9.847032
A13: EQT | B13: =Input_Finanzen!B13 -> EQT Corp. | C13: E&P | D13: =IFERROR(Input_Finanzen!I13/Input_Finanzen!L13,"n/a") -> 1.3144444 | E13: =IFERROR(Input_Finanzen!L13/Input_Finanzen!M13,"n/a") -> 13.334853 | F13: =IFERROR(Input_Finanzen!J13/Input_Finanzen!M13,"n/a") -> 7.4073399 | G13: =IFERROR(Input_Finanzen!P13,"n/a") -> 2837.6 | H13: =IF(Input_Finanzen!I13<=0,"n.m.",IFERROR(Input_Finanzen!P13/Input_Finanzen!I13,"n/a")) -> 0.36902269 | I13: =IFERROR(Input_Finanzen!P13/Input_Finanzen!G13,"n/a") -> 0.36378088 | J13: =IFERROR(Input_Finanzen!O13/Input_Finanzen!K13,"n/a") -> 0.88001846 | K13: =IFERROR(IF(Input_Finanzen!Q13="",0,Input_Finanzen!Q13)+IF(Input_Finanzen!R13="",0,Input_Finanzen!R13),"n/a") -> 389.6 | L13: =IF(Input_Finanzen!P13<=0,"n.m.",IFERROR(K13/Input_Finanzen!P13,"n/a")) -> 0.13729913 | M13: =IF(Input_Finanzen!T13="","n/v",Input_Finanzen!T13) -> 507.1 | N13: =IF(Input_Finanzen!T13="","n/v",IFERROR(Input_Finanzen!T13/Input_Finanzen!G13,"n/a")) -> 0.06501032 | O13: =IF(Input_Ratings!E13="","n/v",Input_Ratings!E13&" ("&Input_Ratings!F13&")") -> Baa3 (positive) | P13: =IF(Input_Ratings!G13="","n/v",Input_Ratings!G13&" ("&Input_Ratings!H13&")") -> BBB- (positive) | Q13: =IF(Input_Ratings!I13="","n/v",Input_Ratings!I13&IF(Input_Ratings!J13=""," "," ("&Input_Ratings!J13&")")) -> BBB- (positive) | R13: =Agentur_Bruecke!J14 -> 1.279342 | S13: =Agentur_Bruecke!Q14 -> 1.38551 | T13: =Agentur_Bruecke!U14 -> 1.279342 | U13: =IFERROR(Input_Finanzen!J13*(1-Input_Finanzen!U13)/(Input_Finanzen!G13+Input_Finanzen!S13),"n/a") -> 0.072187841 | V13: =IF(OR(Input_Finanzen!V13="",Input_Finanzen!W13=""),"n/v",IFERROR(Input_Finanzen!V13/Input_Finanzen!W13,"n/a")) -> 11.832911
