Workbook

Sheet README
A1: CONTESTED - raw fetched data
A2: ETHack 2026, Challenge #1. Every number below was pulled from free public government APIs on 12 September 2026.
A4: WHAT THIS FILE IS
A5: The raw inputs only, before any analysis. Nothing here is a score, a rank or a conclusion.
A6: Four numbers per company go into the calculation. This workbook shows all four, plus every facility they were built from.
A8: THE FOUR INPUTS
A9: 1. Revenue how much money the company made in FY2023. Audited, from its 10-K.
A10: 2. Reported emissions tonnes CO2e the company itself reported to the US EPA, summed over its facilities.
A11: 3. Industry code (NAICS) the official classification, e.g. 331110 = Iron and Steel Mills.
A12: 4. Industry factor (EEIO) EPA's published kg CO2e per dollar for that industry, whole supply chain.
A14: SOURCES, ALL FREE, NO API KEY
A15: Revenue SEC XBRL frames API https://data.sec.gov/api/xbrl/frames/us-gaap/<TAG>/USD/CY2023.json
... A41: 12 of 30 companies reported no emissions at all. That absence is itself a finding, not a gap to paper over.

Sheet Company inputs
A1: IDENTIFIERS | G1: SEC revenue | J1: EPA GHGRP reported emissions | P1: EPA EEIO industry factor | T1: AUDIT
A2: Ticker | B2: Company | C2: GICS sector | D2: SEC CIK | E2: SEC registrant name | F2: NAICS code | G2: Revenue FY2023 (USD) | H2: XBRL tag used | I2: Market cap (USD) | J2: Reported Scope 1, 100% consolidation (tCO2e) | K2: Reported Scope 1, equity share (tCO2e) | L2: Facilities found | M2: Facilities with an emissions value | N2: EPA parent search string | O2: Facilities with NO value | P2: EEIO NAICS matched | Q2: EEIO industry title | R2: Factor with margins (kg CO2e/2022 USD) | S2: Factor without margins | T2: SUMIF check from facilities sheet | U2: Difference vs column J | V2: Note
A3: units -> | G3: USD | I3: USD | J3: tonnes CO2e | K3: tonnes CO2e | R3: kg CO2e per USD | S3: kg CO2e per USD | T3: tonnes CO2e | U3: tonnes CO2e
A4: XOM | B4: Exxon Mobil | C4: Energy | D4: 0002115436 | E4: ExxonMobil Holdings Corp | F4: 324110 | J4: 3.9157197e+08 | K4: 3.8066908e+08 | L4: 130 | M4: 64 | N4: EXXON | O4: =L4-M4 -> 66 | P4: 324110 | Q4: Petroleum Refineries | R4: 0.27 | S4: 0.248 | T4: =SUMIF('EPA facilities'!$A$2:$A$600,$A4,'EPA facilities'!$G$2:$G$600) -> 3.9157197e+08 | U4: =IFERROR(ROUND(T4-J4,1),"n/a") -> 0 | V4: huge disclosed Scope 1; expect robustly dirty
A5: CVX | B5: Chevron | C5: Energy | D5: 0000093410 | E5: CHEVRON CORP | F5: 324110 | G5: 196913000000 | H5: RevenueFromContractWithCustomerExcludingAssessedTax | J5: 2.0655173e+08 | K5: 1.9909879e+08 | L5: 92 | M5: 55 | N5: CHEVRON | O5: =L5-M5 -> 37 | P5: 324110 | Q5: Petroleum Refineries | R5: 0.27 | S5: 0.248 | T5: =SUMIF('EPA facilities'!$A$2:$A$600,$A5,'EPA facilities'!$G$2:$G$600) -> 2.0655173e+08 | U5: =IFERROR(ROUND(T5-J5,1),"n/a") -> 0 | V5: refining + upstream
A6: OKE | B6: ONEOK | C6: Energy | D6: 0001039684 | E6: ONEOK INC /NEW/ | F6: 486210 | G6: 17677000000 | H6: RevenueFromContractWithCustomerExcludingAssessedTax | J6: 84364928 | K6: 75252961 | L6: 56 | M6: 39 | N6: ONEOK | O6: =L6-M6 -> 17 | P6: 486210 | Q6: Pipeline Transportation of Natural Gas | R6: 1.619 | S6: 1.619 | T6: =SUMIF('EPA facilities'!$A$2:$A$600,$A6,'EPA facilities'!$G$2:$G$600) -> 84364928 | U6: =IFERROR(ROUND(T6-J6,1),"n/a") -> 0 | V6: midstream pipelines
A7: NUE | B7: Nucor | C7: Materials | D7: 0000073309 | E7: NUCOR CORP | F7: 331110 | G7: 34714000000 | H7: RevenueFromContractWithCustomerExcludingAssessedTax | J7: 5761770.6 | K7: 5497406.2 | L7: 26 | M7: 26 | N7: NUCOR | O7: =L7-M7 -> 0 | P7: 331110 | Q7: Iron and Steel Mills and Ferroalloy Manufacturing | R7: 0.787 | S7: 0.769 | T7: =SUMIF('EPA facilities'!$A$2:$A$600,$A7,'EPA facilities'!$G$2:$G$600) -> 5761770.6 | U7: =IFERROR(ROUND(T7-J7,1),"n/a") -> 0 | V7: VERIFIED 26 facilities 5762209 t 2023
A8: DOW | B8: Dow | C8: Materials | D8: 0001751788 | E8: DOW INC. | F8: 325110 | G8: 44622000000 | H8: Revenues | L8: 1 | M8: 0 | N8: DOW CHEMICAL | O8: =L8-M8 -> 1 | P8: 325110 | Q8: Petrochemical Manufacturing | R8: 0.811 | S8: 0.794 | T8: =SUMIF('EPA facilities'!$A$2:$A$600,$A8,'EPA facilities'!$G$2:$G$600) -> 0 | U8: =IFERROR(ROUND(T8-J8,1),"n/a") -> 0 | V8: petrochemicals
A9: SHW | B9: Sherwin-Williams | C9: Materials | D9: 0000089800 | E9: SHERWIN WILLIAMS CO | F9: 325510 | G9: 23051900000 | H9: RevenueFromContractWithCustomerExcludingAssessedTax | L9: 1 | M9: 0 | N9: SHERWIN | O9: =L9-M9 -> 1 | P9: 325510 | Q9: Paint and Coating Manufacturing | R9: 0.291 | S9: 0.264 | T9: =SUMIF('EPA facilities'!$A$2:$A$600,$A9,'EPA facilities'!$G$2:$G$600) -> 0 | U9: =IFERROR(ROUND(T9-J9,1),"n/a") -> 0 | V9: coatings; lighter industry
A10: UNP | B10: Union Pacific | C10: Industrials | D10: 0000100885 | E10: UNION PACIFIC CORP | F10: 482111 | G10: 24119000000 | H10: RevenueFromContractWithCustomerExcludingAssessedTax | L10: 0 | M10: 0 | N10: UNION PACIFIC | O10: =L10-M10 -> 0 | P10: 482111 | Q10: Line-Haul Railroads | R10: 0.466 | S10: 0.466 | T10: =SUMIF('EPA facilities'!$A$2:$A$600,$A10,'EPA facilities'!$G$2:$G$600) -> 0 | U10: =IFERROR(ROUND(T10-J10,1),"n/a") -> 0 | V10: diesel fleet; Scope 1 heavy
A11: CAT | B11: Caterpillar | C11: Industrials | D11: 0000018230 | E11: CATERPILLAR INC | F11: 333120 | G11: 67060000000 | H11: Revenues | J11: 456901.74 | K11: 456901.74 | L11: 8 | M11: 7 | N11: CATERPILLAR | O11: =L11-M11 -> 1 | P11: 333120 | Q11: Construction Machinery Manufacturing | R11: 0.228 | S11: 0.201 | T11: =SUMIF('EPA facilities'!$A$2:$A$600,$A11,'EPA facilities'!$G$2:$G$600) -> 456901.74 | U11: =IFERROR(ROUND(T11-J11,1),"n/a") -> 0 | V11: use-phase Scope 3 dominant
A12: DE | B12: Deere | C12: Industrials | D12: 0000315189 | E12: DEERE & CO | F12: 333111 | G12: 61251000000 | H12: Revenues | J12: 45075.88 | K12: 45075.88 | L12: 3 | M12: 1 | N12: DEERE | O12: =L12-M12 -> 2 | P12: 333111 | Q12: Farm Machinery and Equipment Manufacturing | R12: 0.22 | S12: 0.191 | T12: =SUMIF('EPA facilities'!$A$2:$A$600,$A12,'EPA facilities'!$G$2:$G$600) -> 45075.88 | U12: =IFERROR(ROUND(T12-J12,1),"n/a") -> 0 | V12: use-phase Scope 3 dominant
A13: F | B13: Ford Motor | C13: Consumer Discretionary | D13: 0000037996 | E13: FORD MOTOR CO | F13: 336111 | G13: 176191000000 | H13: RevenueFromContractWithCustomerExcludingAssessedTax | J13: 497625.12 | K13: 497625.12 | L13: 15 | M13: 10 | N13: FORD MOTOR | O13: =L13-M13 -> 5 | P13: 336111 | Q13: Automobile Manufacturing | R13: 0.24 | S13: 0.19 | T13: =SUMIF('EPA facilities'!$A$2:$A$600,$A13,'EPA facilities'!$G$2:$G$600) -> 497625.12 | U13: =IFERROR(ROUND(T13-J13,1),"n/a") -> 0 | V13: VERIFIED 16 facilities 497625 t 2023
A14: GM | B14: General Motors | C14: Consumer Discretionary | D14: 0001467858 | E14: General Motors Co | F14: 336111 | G14: 157658000000 | H14: RevenueFromContractWithCustomerExcludingAssessedTax | J14: 598855.55 | K14: 598855.55 | L14: 18 | M14: 14 | N14: GENERAL MOTORS | O14: =L14-M14 -> 4 | P14: 336111 | Q14: Automobile Manufacturing | R14: 0.24 | S14: 0.19 | T14: =SUMIF('EPA facilities'!$A$2:$A$600,$A14,'EPA facilities'!$G$2:$G$600) -> 598855.55 | U14: =IFERROR(ROUND(T14-J14,1),"n/a") -> 0 | V14: peer to Ford
A15: AMZN | B15: Amazon | C15: Consumer Discretionary | D15: 0001018724 | E15: AMAZON COM INC | F15: 454110 | G15: 574785000000 | H15: RevenueFromContractWithCustomerExcludingAssessedTax | L15: 0 | M15: 0 | N15: AMAZON | O15: =L15-M15 -> 0 | P15: 454110 | Q15: Electronic Shopping and Mail-Order Houses | R15: 0.094 | S15: 0.094 | T15: =SUMIF('EPA facilities'!$A$2:$A$600,$A15,'EPA facilities'!$G$2:$G$600) -> 0 | U15: =IFERROR(ROUND(T15-J15,1),"n/a") -> 0 | V15: logistics + data centres
A16: WMT | B16: Walmart | C16: Consumer Staples | D16: 0000104169 | E16: Walmart Inc. | F16: 452311 | G16: 642637000000 | H16: RevenueFromContractWithCustomerExcludingAssessedTax | L16: 1 | M16: 0 | N16: WAL-MART | O16: =L16-M16 -> 1 | P16: 452311 | Q16: Warehouse Clubs and Supercenters | R16: 0.164 | S16: 0.164 | T16: =SUMIF('EPA facilities'!$A$2:$A$600,$A16,'EPA facilities'!$G$2:$G$600) -> 0 | U16: =IFERROR(ROUND(T16-J16,1),"n/a") -> 0 | V16: VERIFIED no emissions figure; supplier subparts only
A17: PG | B17: Procter & Gamble | C17: Consumer Staples | D17: 0000080424 | E17: PROCTER & GAMBLE Co | F17: 325610 | G17: 82006000000 | H17: Revenues | J17: 1692217.8 | K17: 1676670.2 | L17: 10 | M17: 10 | N17: PROCTER | O17: =L17-M17 -> 0 | T17: =SUMIF('EPA facilities'!$A$2:$A$600,$A17,'EPA facilities'!$G$2:$G$600) -> 1692217.8 | U17: =IFERROR(ROUND(T17-J17,1),"n/a") -> 0 | V17: consumer goods supply chain
A18: KO | B18: Coca-Cola | C18: Consumer Staples | D18: 0000021344 | E18: COCA COLA CO | F18: 312111 | G18: 45754000000 | H18: Revenues | L18: 0 | M18: 0 | N18: COCA COLA | O18: =L18-M18 -> 0 | P18: 312111 | Q18: Soft Drink Manufacturing | R18: 0.214 | S18: 0.173 | T18: =SUMIF('EPA facilities'!$A$2:$A$600,$A18,'EPA facilities'!$G$2:$G$600) -> 0 | U18: =IFERROR(ROUND(T18-J18,1),"n/a") -> 0 | V18: bottling is franchised; boundary games
A19: LLY | B19: Eli Lilly | C19: Health Care | D19: 0000059478 | E19: ELI LILLY & Co | F19: 325412 | G19: 34124000000 | H19: Revenues | J19: 47574.076 | K19: 47574.076 | L19: 1 | M19: 1 | N19: LILLY | O19: =L19-M19 -> 0 | P19: 325412 | Q19: Pharmaceutical Preparation Manufacturing | R19: 0.099 | S19: 0.045 | T19: =SUMIF('EPA facilities'!$A$2:$A$600,$A19,'EPA facilities'!$G$2:$G$600) -> 47574.076 | U19: =IFERROR(ROUND(T19-J19,1),"n/a") -> 0 | V19: pharma manufacturing
A20: UNH | B20: UnitedHealth | C20: Health Care | D20: 0000731766 | E20: UNITEDHEALTH GROUP INC | F20: 524114 | G20: 371622000000 | H20: Revenues | L20: 0 | M20: 0 | N20: UNITEDHEALTH | O20: =L20-M20 -> 0 | P20: 524114 | Q20: Direct Health and Medical Insurance Carriers | R20: 0.033 | S20: 0.033 | T20: =SUMIF('EPA facilities'!$A$2:$A$600,$A20,'EPA facilities'!$G$2:$G$600) -> 0 | U20: =IFERROR(ROUND(T20-J20,1),"n/a") -> 0 | V20: insurer; almost no Scope 1
A21: JNJ | B21: Johnson & Johnson | C21: Health Care | D21: 0000200406 | E21: JOHNSON & JOHNSON | F21: 325412 | G21: 85159000000 | H21: RevenueFromContractWithCustomerExcludingAssessedTax | J21: 165236.41 | K21: 105133.4 | L21: 7 | M21: 4 | N21: JOHNSON | O21: =L21-M21 -> 3 | P21: 325412 | Q21: Pharmaceutical Preparation Manufacturing | R21: 0.099 | S21: 0.045 | T21: =SUMIF('EPA facilities'!$A$2:$A$600,$A21,'EPA facilities'!$G$2:$G$600) -> 165236.41 | U21: =IFERROR(ROUND(T21-J21,1),"n/a") -> 0 | V21: pharma + devices
A22: JPM | B22: JPMorgan Chase | C22: Financials | D22: 0000019617 | E22: JPMORGAN CHASE & CO | F22: 522110 | G22: 158104000000 | H22: Revenues | L22: 1 | M22: 0 | N22: JP MORGAN | O22: =L22-M22 -> 1 | P22: 522110 | Q22: Commercial Banking | R22: 0.059 | S22: 0.059 | T22: =SUMIF('EPA facilities'!$A$2:$A$600,$A22,'EPA facilities'!$G$2:$G$600) -> 0 | U22: =IFERROR(ROUND(T22-J22,1),"n/a") -> 0 | V22: VERIFIED zero GHGRP rows 2023
A23: BAC | B23: Bank of America | C23: Financials | D23: 0000070858 | E23: BANK OF AMERICA CORP /DE/ | F23: 522110 | G23: 102769000000 | H23: Revenues | L23: 0 | M23: 0 | N23: BANK OF AMERICA | O23: =L23-M23 -> 0 | P23: 522110 | Q23: Commercial Banking | R23: 0.059 | S23: 0.059 | T23: =SUMIF('EPA facilities'!$A$2:$A$600,$A23,'EPA facilities'!$G$2:$G$600) -> 0 | U23: =IFERROR(ROUND(T23-J23,1),"n/a") -> 0 | V23: peer to JPM
A24: GS | B24: Goldman Sachs | C24: Financials | D24: 0000886982 | E24: GOLDMAN SACHS GROUP INC | F24: 523110 | G24: 46254000000 | H24: RevenuesNetOfInterestExpense | J24: 52140.304 | K24: 15642.091 | L24: 1 | M24: 1 | N24: GOLDMAN | O24: =L24-M24 -> 0 | P24: 523110 | Q24: Investment Banking and Securities Dealing | R24: 0.043 | S24: 0.043 | T24: =SUMIF('EPA facilities'!$A$2:$A$600,$A24,'EPA facilities'!$G$2:$G$600) -> 52140.304 | U24: =IFERROR(ROUND(T24-J24,1),"n/a") -> 0 | V24: investment bank
A25: AAPL | B25: Apple | C25: Information Technology | D25: 0000320193 | E25: Apple Inc. | F25: 334220 | G25: 383285000000 | H25: RevenueFromContractWithCustomerExcludingAssessedTax | J25: 11059250 | K25: 11059250 | L25: 3 | M25: 3 | N25: APPLE | O25: =L25-M25 -> 0 | P25: 334220 | Q25: Radio and Television Broadcasting and Wireless Communications Equipment Manufacturing | R25: 0.111 | S25: 0.065 | T25: =SUMIF('EPA facilities'!$A$2:$A$600,$A25,'EPA facilities'!$G$2:$G$600) -> 11059250 | U25: =IFERROR(ROUND(T25-J25,1),"n/a") -> 0 | V25: supply chain is the footprint
A26: MSFT | B26: Microsoft | C26: Information Technology | D26: 0000789019 | E26: MICROSOFT CORP | F26: 513210 | G26: 211915000000 | H26: RevenueFromContractWithCustomerExcludingAssessedTax | L26: 0 | M26: 0 | N26: MICROSOFT | O26: =L26-M26 -> 0 | T26: =SUMIF('EPA facilities'!$A$2:$A$600,$A26,'EPA facilities'!$G$2:$G$600) -> 0 | U26: =IFERROR(ROUND(T26-J26,1),"n/a") -> 0 | V26: data centres
A27: NVDA | B27: NVIDIA | C27: Information Technology | D27: 0001045810 | E27: NVIDIA CORP | F27: 334413 | G27: 60922000000 | H27: Revenues | L27: 0 | M27: 0 | N27: NVIDIA | O27: =L27-M27 -> 0 | P27: 334413 | Q27: Semiconductor and Related Device Manufacturing | R27: 0.215 | S27: 0.188 | T27: =SUMIF('EPA facilities'!$A$2:$A$600,$A27,'EPA facilities'!$G$2:$G$600) -> 0 | U27: =IFERROR(ROUND(T27-J27,1),"n/a") -> 0 | V27: fabless; almost nothing owned
A28: META | B28: Meta Platforms | C28: Communication Services | D28: 0001326801 | E28: Meta Platforms, Inc. | F28: 516210 | G28: 134902000000 | H28: RevenueFromContractWithCustomerExcludingAssessedTax | L28: 0 | M28: 0 | N28: FACEBOOK | O28: =L28-M28 -> 0 | T28: =SUMIF('EPA facilities'!$A$2:$A$600,$A28,'EPA facilities'!$G$2:$G$600) -> 0 | U28: =IFERROR(ROUND(T28-J28,1),"n/a") -> 0 | V28: data centres; name changed 2021
A29: GOOGL | B29: Alphabet | C29: Communication Services | D29: 0001652044 | E29: Alphabet Inc. | F29: 516210 | G29: 307394000000 | H29: RevenueFromContractWithCustomerExcludingAssessedTax | J29: 56418.04 | K29: 15853.469 | L29: 1 | M29: 1 | N29: ALPHABET | O29: =L29-M29 -> 0 | T29: =SUMIF('EPA facilities'!$A$2:$A$600,$A29,'EPA facilities'!$G$2:$G$600) -> 56418.04 | U29: =IFERROR(ROUND(T29-J29,1),"n/a") -> 0 | V29: data centres
A30: DIS | B30: Walt Disney | C30: Communication Services | D30: 0001744489 | E30: Walt Disney Co | F30: 512110 | G30: 88898000000 | H30: Revenues | J30: 219040.33 | K30: 216849.92 | L30: 1 | M30: 1 | N30: DISNEY | O30: =L30-M30 -> 0 | P30: 512110 | Q30: Motion Picture and Video Production | R30: 0.052 | S30: 0.047 | T30: =SUMIF('EPA facilities'!$A$2:$A$600,$A30,'EPA facilities'!$G$2:$G$600) -> 219040.33 | U30: =IFERROR(ROUND(T30-J30,1),"n/a") -> 0 | V30: parks + media
A31: DUK | B31: Duke Energy | C31: Utilities | D31: 0001326160 | E31: Duke Energy CORP | F31: 221112 | G31: 28674000000 | H31: RevenueFromContractWithCustomerIncludingAssessedTax | J31: 1.0968664e+08 | K31: 1.0872069e+08 | L31: 54 | M31: 48 | N31: DUKE ENERGY | O31: =L31-M31 -> 6 | T31: =SUMIF('EPA facilities'!$A$2:$A$600,$A31,'EPA facilities'!$G$2:$G$600) -> 1.0968664e+08 | U31: =IFERROR(ROUND(T31-J31,1),"n/a") -> 0 | V31: expect very large disclosed Scope 1
A32: NEE | B32: NextEra Energy | C32: Utilities | D32: 0000753308 | E32: NEXTERA ENERGY INC | F32: 221112 | G32: 24800000000 | H32: RevenueFromContractWithCustomerIncludingAssessedTax | J32: 53653265 | K32: 42867508 | L32: 30 | M32: 26 | N32: NEXTERA | O32: =L32-M32 -> 4 | T32: =SUMIF('EPA facilities'!$A$2:$A$600,$A32,'EPA facilities'!$G$2:$G$600) -> 53653265 | U32: =IFERROR(ROUND(T32-J32,1),"n/a") -> 0 | V32: subsidiary files as Florida Power and Light
A33: SO | B33: Southern Company | C33: Utilities | D33: 0000092122 | E33: SOUTHERN CO | F33: 221112 | G33: 25253000000 | H33: Revenues | J33: 1.3857686e+08 | K33: 1.2457434e+08 | L33: 102 | M33: 72 | N33: SOUTHERN | O33: =L33-M33 -> 30 | T33: =SUMIF('EPA facilities'!$A$2:$A$600,$A33,'EPA facilities'!$G$2:$G$600) -> 1.3857686e+08 | U33: =IFERROR(ROUND(T33-J33,1),"n/a") -> 0 | V33: subsidiaries file separately
A35: TOTALS | G35: =SUM(G4:G33) -> 4212513900000 | I35: =SUM(I4:I33) -> 0 | J35: =SUM(J4:J33) -> 1.0050575e+09 | K35: =SUM(K4:K33) -> 9.514162e+08 | L35: =SUM(L4:L33) -> 562 | M35: =SUM(M4:M33) -> 383 | T35: =SUM(T4:T33) -> 1.0050575e+09
A37: Blue = fetched from an API, raw. Black = formula, audit it yourself. Orange rows have no revenue and cannot produce an intensity.

Sheet EPA facilities
A1: Ticker | B1: EPA facility ID | C1: Facility name | D1: State | E1: Facility NAICS | F1: Company ownership share | G1: Reported emissions (tCO2e) | H1: EPA parent company string, verbatim
A2: XOM | B2: 1001874 | C2: BPXA GATHERING CENTER #2 | D2: AK | E2: 211111 | F2: 0.364 | H2: EXXON MOBIL CORP (36.4%); CONOCOPHILLIPS (36.1%); BP AMERICA INC (26.4%); CHEVRON CORP (1.2%)
A3: XOM | B3: 1013842 | C3: PHP Junction Compressor Station | D3: TX | E3: 486210 | F3: 0.1999 | G3: 127570.12 | H3: APA CORP (26.67%); EAGLECLAW MIDSTREAM SERVICES LLC (26.67%); KINDER MORGAN INC (26.67%); EXXON MOBIL CORP (19.99%)
A4: XOM | B4: 1001799 | C4: BPXA FLOW STATION #1 | D4: AK | E4: 211111 | F4: 0.364 | H4: EXXON MOBIL CORP (36.4%); CONOCOPHILLIPS (36.1%); BP AMERICA INC (26.4%); CHEVRON CORP (1.2%)
A5: XOM | B5: 1004142 | C5: XTO - Midpt Station | D5: TX | E5: 211111 | F5: 1 | H5: EXXONMOBIL CORP (100%)
A6: XOM | B6: 1001875 | C6: BPXA GATHERING CENTER #3 | D6: AK | E6: 211111 | F6: 0.364 | H6: EXXON MOBIL CORP (36.4%); CONOCOPHILLIPS (36.1%); BP AMERICA INC (26.4%); CHEVRON CORP (1.2%)
A7: XOM | B7: 1005393 | C7: XTO - Chandler Station | D7: TX | E7: 211111 | F7: 1 | H7: EXXONMOBIL CORP (100%)
A8: XOM | B8: 1002672 | C8: Trawick Central Station | D8: TX | E8: 211111 | F8: 1 | H8: EXXONMOBIL CORP (100%)
A9: XOM | B9: 1013843 | C9: PHP 285 Compressor Station | D9: TX | E9: 486210 | F9: 0.2 | G9: 125913.78 | H9: APA CORP (26.67%); EAGLECLAW MIDSTREAM SERVICES LLC (26.67%); KINDER MORGAN INC (26.67%); EXXON MOBIL CORP (20%)
A10: XOM | B10: 1003484 | C10: EXXONMOBIL CHEMICAL CO - BATON ROUGE PLASTICS PLANT | D10: LA | E10: 325211 | F10: 1 | G10: 74312.72 | H10: EXXON MOBIL CORP (100%)
A11: XOM | B11: 1007643 | C11: EXXONMOBIL BATON ROUGE REFINERY AND CHEMICAL PLANT | D11: LA | E11: 324110 | F11: 1 | G11: 86892466 | H11: EXXON MOBIL CORP (100%)
A12: XOM | B12: 1006274 | C12: EXXONMOBIL CHEMICAL MONT BELVIEU PLASTICS PLANT | D12: TX | E12: 325211 | F12: 1 | G12: 93204.2 | H12: EXXON MOBIL CORP (100%)
A13: XOM | B13: 1005858 | C13: DENVER UNIT CO 2 RECOVERY PLANT | D13: TX | E13: 211120 | F13: 0.12 | G13: 99720.708 | H13: OCCIDENTAL PETROLEUM CORP (53%); CHEVRON CORP (17%); CONOCOPHILLIPS (14%); EXXON MOBIL CORP (12%); ARIEL EXPLORATION INC (1%); COTERRA ENERGY INC (1%); DEVON ENERGY CORP (1%); PENROC OIL CORP (1%)
A14: XOM | B14: 1002676 | C14: Hawkins Gas Plant | D14: TX | E14: 211130 | F14: 1 | G14: 81902.414 | H14: EXXON MOBIL CORP (100%)
A15: XOM | B15: 1012581 | C15: XTO Energy Inc 595 Piceance GB | D15: NM | E15: 211130 | F15: 1 | H15: EXXON MOBIL CORP (100%)
A16: XOM | B16: 1012552 | C16: XTO Energy Inc 350 South Oklahoma Folded Belt GB | D16: OK | E16: 211130 | F16: 1 | G16: 258975.74 | H16: EXXON MOBIL CORP (100%)
A17: XOM | B17: 1002735 | C17: EAST VACUUM LIQUID RECOVERY PLANT/CO2 PLANT | D17: NM | E17: 211120 | F17: 0.38 | G17: 17375.132 | H17: MARATHON OIL CORP (5%); CONOCOPHILLIPS (46%); EXXON MOBIL CORP (38%); APA CORP (11%)
A18: XOM | B18: 1013841 | C18: PHP Big Lake Compressor Station | D18: TX | E18: 486210 | F18: 0.1999 | G18: 136720.21 | H18: APA CORP (26.67%); EAGLECLAW MIDSTREAM SERVICES LLC (26.67%); KINDER MORGAN INC (26.67%); EXXON MOBIL CORP (19.99%)
A19: XOM | B19: 1012546 | C19: XTO Energy Inc 507 Central Western Overthrust GB | D19: OK | E19: 211130 | F19: 1 | G19: 2090.75 | H19: EXXON MOBIL CORP (100%)
A20: XOM | B20: 1009388 | C20: XTO Energy Inc 420 Fort Worth Syncline | D20: TX | E20: 211130 | F20: 1 | H20: EXXON MOBIL CORP (100%)
A21: XOM | B21: 1007959 | C21: Exxonmobil Beaumont Refinery | D21: TX | E21: 324110 | F21: 1 | G21: 89058742 | H21: EXXON MOBIL CORP (100%)
A22: XOM | B22: 1005405 | C22: XTO - Kindon Station | D22: TX | E22: 211111 | F22: 1 | H22: EXXONMOBIL CORP (100%)
A23: XOM | B23: 1011100 | C23: Cross Timbers Energy, LLC - San Juan Basin 580 | D23: TX | E23: 211130 | F23: 0.5 | G23: 17887.192 | H23: EXXON MOBIL CORP (50%); MORNINGSTAR PARTNERS LP (50%)
A24: XOM | B24: 1010591 | C24: XTO Stonefly Compressor Station | D24: AR | E24: 211111 | F24: 1 | H24: EXXONMOBIL CORP (100%)
A25: XOM | B25: 1010913 | C25: XTO - Jefferson Township Station | D25: PA | E25: 211111 | F25: 1 | H25: EXXONMOBIL CORP (100%)
A26: XOM | B26: 1012596 | C26: XTO Energy Inc 220 Gulf Coast GB | D26: TX | E26: 211130 | F26: 1 | G26: 64725.03 | H26: EXXON MOBIL CORP (100%)
A27: XOM | B27: 1012568 | C27: XTO Energy Inc 395 Williston GB | D27: ND | E27: 211130 | F27: 1 | G27: 101784.24 | H27: EXXON MOBIL CORP (100%)
A28: XOM | B28: 1014396 | C28: Cowboy CDP | D28: NM | E28: 211120 | F28: 1 | G28: 73088.92 | H28: EXXON MOBIL CORP (100%)
A29: XOM | B29: 1012588 | C29: XTO Energy Inc 580 San Juan GB | D29: NM | E29: 211111 | F29: 1 | H29: EXXONMOBIL CORP (100%)
A30: XOM | B30: 1005409 | C30: XTO - BOA GAS TREATING PLANT | D30: TX | E30: 211111 | F30: 1 | H30: EXXONMOBIL CORP (100%);
A31: XOM | B31: 1004134 | C31: XTO - Azle Station | D31: TX | E31: 211111 | F31: 1 | H31: EXXONMOBIL CORP (100%)
A32: XOM | B32: 1005793 | C32: XTO-Freestone Central Station | D32: TX | E32: 211111 | F32: 1 | H32: EXXONMOBIL CORP (100%)
A33: XOM | B33: 1006801 | C33: EXXONMOBIL CHEMICAL CO - BATON ROUGE POLYOLEFINS PLANT | D33: LA | E33: 325211 | F33: 1 | G33: 156123.98 | H33: EXXON MOBIL CORP (100%)
A34: XOM | B34: 1007229 | C34: XTO - Teague NE Station | D34: TX | E34: 211111 | F34: 1 | H34: EXXONMOBIL CORP (100%)
A35: XOM | B35: 1004141 | C35: XTO - Longhorn Station | D35: TX | E35: 211111 | F35: 1 | H35: EXXONMOBIL CORP (100%)
A36: XOM | B36: 1014210 | C36: Gulf Coast Growth Ventures LLC | D36: TX | E36: 325199 | F36: 0.5 | G36: 1597729.7 | H36: EXXON MOBIL CORP (50%); SABIC US HOLDINGS LP (50%)
A37: XOM | B37: 1005404 | C37: XTO - Mitchell Station | D37: TX | E37: 211111 | F37: 1 | H37: EXXONMOBIL CORP (100%)
A38: XOM | B38: 1008078 | C38: XTO Energy Inc 507 Central Western Overthrust | D38: OK | E38: 211130 | F38: 1 | G38: 73130.55 | H38: EXXON MOBIL CORP (100%)
A39: XOM | B39: 1002507 | C39: Mobile Bay - Northwest Gulf Platform | D39: AL | E39: 211130 | F39: 1 | H39: EXXONMOBIL CORP (100%)
A40: XOM | B40: 1005406 | C40: XTO - Morton Station | D40: TX | E40: 211111 | F40: 1 | H40: EXXONMOBIL CORP (100%)
...

Sheet EEIO factors
A1: Ticker | B1: Company | C1: NAICS requested | D1: EEIO NAICS matched | E1: EEIO industry title | F1: Factor with margins | G1: Factor without margins | H1: Difference
A2: XOM | B2: Exxon Mobil | C2: 324110 | D2: 324110 | E2: Petroleum Refineries | F2: 0.27 | G2: 0.248 | H2: =IFERROR(F2-G2,"") -> 0.022
A3: CVX | B3: Chevron | C3: 324110 | D3: 324110 | E3: Petroleum Refineries | F3: 0.27 | G3: 0.248 | H3: =IFERROR(F3-G3,"") -> 0.022
A4: OKE | B4: ONEOK | C4: 486210 | D4: 486210 | E4: Pipeline Transportation of Natural Gas | F4: 1.619 | G4: 1.619 | H4: =IFERROR(F4-G4,"") -> 0
A5: NUE | B5: Nucor | C5: 331110 | D5: 331110 | E5: Iron and Steel Mills and Ferroalloy Manufacturing | F5: 0.787 | G5: 0.769 | H5: =IFERROR(F5-G5,"") -> 0.018
A6: DOW | B6: Dow | C6: 325110 | D6: 325110 | E6: Petrochemical Manufacturing | F6: 0.811 | G6: 0.794 | H6: =IFERROR(F6-G6,"") -> 0.017
A7: SHW | B7: Sherwin-Williams | C7: 325510 | D7: 325510 | E7: Paint and Coating Manufacturing | F7: 0.291 | G7: 0.264 | H7: =IFERROR(F7-G7,"") -> 0.027
A8: UNP | B8: Union Pacific | C8: 482111 | D8: 482111 | E8: Line-Haul Railroads | F8: 0.466 | G8: 0.466 | H8: =IFERROR(F8-G8,"") -> 0
A9: CAT | B9: Caterpillar | C9: 333120 | D9: 333120 | E9: Construction Machinery Manufacturing | F9: 0.228 | G9: 0.201 | H9: =IFERROR(F9-G9,"") -> 0.027
A10: DE | B10: Deere | C10: 333111 | D10: 333111 | E10: Farm Machinery and Equipment Manufacturing | F10: 0.22 | G10: 0.191 | H10: =IFERROR(F10-G10,"") -> 0.029
A11: F | B11: Ford Motor | C11: 336111 | D11: 336111 | E11: Automobile Manufacturing | F11: 0.24 | G11: 0.19 | H11: =IFERROR(F11-G11,"") -> 0.05
A12: GM | B12: General Motors | C12: 336111 | D12: 336111 | E12: Automobile Manufacturing | F12: 0.24 | G12: 0.19 | H12: =IFERROR(F12-G12,"") -> 0.05
A13: AMZN | B13: Amazon | C13: 454110 | D13: 454110 | E13: Electronic Shopping and Mail-Order Houses | F13: 0.094 | G13: 0.094 | H13: =IFERROR(F13-G13,"") -> 0
A14: WMT | B14: Walmart | C14: 452311 | D14: 452311 | E14: Warehouse Clubs and Supercenters | F14: 0.164 | G14: 0.164 | H14: =IFERROR(F14-G14,"") -> 0
A15: PG | B15: Procter & Gamble | C15: 325610 | E15: NO FACTOR FOUND | H15: =IFERROR(F15-G15,"") -> 0
A16: KO | B16: Coca-Cola | C16: 312111 | D16: 312111 | E16: Soft Drink Manufacturing | F16: 0.214 | G16: 0.173 | H16: =IFERROR(F16-G16,"") -> 0.041
A17: LLY | B17: Eli Lilly | C17: 325412 | D17: 325412 | E17: Pharmaceutical Preparation Manufacturing | F17: 0.099 | G17: 0.045 | H17: =IFERROR(F17-G17,"") -> 0.054
A18: UNH | B18: UnitedHealth | C18: 524114 | D18: 524114 | E18: Direct Health and Medical Insurance Carriers | F18: 0.033 | G18: 0.033 | H18: =IFERROR(F18-G18,"") -> 0
A19: JNJ | B19: Johnson & Johnson | C19: 325412 | D19: 325412 | E19: Pharmaceutical Preparation Manufacturing | F19: 0.099 | G19: 0.045 | H19: =IFERROR(F19-G19,"") -> 0.054
A20: JPM | B20: JPMorgan Chase | C20: 522110 | D20: 522110 | E20: Commercial Banking | F20: 0.059 | G20: 0.059 | H20: =IFERROR(F20-G20,"") -> 0
A21: BAC | B21: Bank of America | C21: 522110 | D21: 522110 | E21: Commercial Banking | F21: 0.059 | G21: 0.059 | H21: =IFERROR(F21-G21,"") -> 0
A22: GS | B22: Goldman Sachs | C22: 523110 | D22: 523110 | E22: Investment Banking and Securities Dealing | F22: 0.043 | G22: 0.043 | H22: =IFERROR(F22-G22,"") -> 0
A23: AAPL | B23: Apple | C23: 334220 | D23: 334220 | E23: Radio and Television Broadcasting and Wireless Communications Equipment Manufacturing | F23: 0.111 | G23: 0.065 | H23: =IFERROR(F23-G23,"") -> 0.046
A24: MSFT | B24: Microsoft | C24: 513210 | E24: NO FACTOR FOUND | H24: =IFERROR(F24-G24,"") -> 0
A25: NVDA | B25: NVIDIA | C25: 334413 | D25: 334413 | E25: Semiconductor and Related Device Manufacturing | F25: 0.215 | G25: 0.188 | H25: =IFERROR(F25-G25,"") -> 0.027
A26: META | B26: Meta Platforms | C26: 516210 | E26: NO FACTOR FOUND | H26: =IFERROR(F26-G26,"") -> 0
A27: GOOGL | B27: Alphabet | C27: 516210 | E27: NO FACTOR FOUND | H27: =IFERROR(F27-G27,"") -> 0
A28: DIS | B28: Walt Disney | C28: 512110 | D28: 512110 | E28: Motion Picture and Video Production | F28: 0.052 | G28: 0.047 | H28: =IFERROR(F28-G28,"") -> 0.005
A29: DUK | B29: Duke Energy | C29: 221112 | E29: NO FACTOR FOUND | H29: =IFERROR(F29-G29,"") -> 0
A30: NEE | B30: NextEra Energy | C30: 221112 | E30: NO FACTOR FOUND | H30: =IFERROR(F30-G30,"") -> 0
A31: SO | B31: Southern Company | C31: 221112 | E31: NO FACTOR FOUND | H31: =IFERROR(F31-G31,"") -> 0
A34: Unit: kg CO2e per 2022 USD of purchaser price. All GHGs, AR5 100-year GWP. Source: EPA Supply Chain GHG Emission Factors v1.3 by NAICS-6.

Sheet Data gaps
A1: Data gaps, stated openly
A2: Every absence below is documented rather than filled in silently. How you treat them is the whole subject of the analysis.
A4: Ticker | B4: Company | C4: What is missing | D4: Why | E4: Consequence
A5: XOM | B5: Exxon Mobil | C5: Revenue | D5: No value under any of the 5 XBRL tags tried. CIK 0002115436 resolved to 'ExxonMobil Holdings Corp', which may be the wrong legal entity. | E5: No denominator, so no intensity. Excluded from every specification.
A6: DOW | B6: Dow | C6: Reported Scope 1 emissions | D6: EPA search 'DOW CHEMICAL' returned 1 facilities, 0 with a CO2e value. | E6: Handled by the missing-data rule: excluded, ranked worst, or replaced by the estimate. Three different answers.
A7: SHW | B7: Sherwin-Williams | C7: Reported Scope 1 emissions | D7: EPA search 'SHERWIN' returned 1 facilities, 0 with a CO2e value. | E7: Handled by the missing-data rule: excluded, ranked worst, or replaced by the estimate. Three different answers.
A8: UNP | B8: Union Pacific | C8: Reported Scope 1 emissions | D8: EPA search 'UNION PACIFIC' returned 0 facilities, 0 with a CO2e value. | E8: Handled by the missing-data rule: excluded, ranked worst, or replaced by the estimate. Three different answers.
A9: AMZN | B9: Amazon | C9: Reported Scope 1 emissions | D9: EPA search 'AMAZON' returned 0 facilities, 0 with a CO2e value. | E9: Handled by the missing-data rule: excluded, ranked worst, or replaced by the estimate. Three different answers.
A10: WMT | B10: Walmart | C10: Reported Scope 1 emissions | D10: EPA search 'WAL-MART' returned 1 facilities, 0 with a CO2e value. | E10: Handled by the missing-data rule: excluded, ranked worst, or replaced by the estimate. Three different answers.
A11: PG | B11: Procter & Gamble | C11: Industry emission factor | D11: NAICS 325610 not present in the EPA table, which omits most finance and information sectors. | E11: No modelled estimate. Ranked only where the worst-case rule applies.
A12: KO | B12: Coca-Cola | C12: Reported Scope 1 emissions | D12: EPA search 'COCA COLA' returned 0 facilities, 0 with a CO2e value. | E12: Handled by the missing-data rule: excluded, ranked worst, or replaced by the estimate. Three different answers.
A13: UNH | B13: UnitedHealth | C13: Reported Scope 1 emissions | D13: EPA search 'UNITEDHEALTH' returned 0 facilities, 0 with a CO2e value. | E13: Handled by the missing-data rule: excluded, ranked worst, or replaced by the estimate. Three different answers.
A14: JPM | B14: JPMorgan Chase | C14: Reported Scope 1 emissions | D14: EPA search 'JP MORGAN' returned 1 facilities, 0 with a CO2e value. | E14: Handled by the missing-data rule: excluded, ranked worst, or replaced by the estimate. Three different answers.
A15: BAC | B15: Bank of America | C15: Reported Scope 1 emissions | D15: EPA search 'BANK OF AMERICA' returned 0 facilities, 0 with a CO2e value. | E15: Handled by the missing-data rule: excluded, ranked worst, or replaced by the estimate. Three different answers.
... A24: SO | B24: Southern Company | C24: Industry emission factor | D24: NAICS 221112 not present in the EPA table, which omits most finance and information sectors. | E24: No modelled estimate. Ranked only where the worst-case rule applies.
A27: 20 gaps across 30 companies.

Sheet Provenance
A1: Provenance: the exact call behind every field
A2: Pulled 12 September 2026. All endpoints are free and require no API key. 132 responses were cached to data/raw/ and can be re-inspected.
A4: Field | B4: Source | C4: Exact endpoint or file | D4: Notes
A5: SEC CIK | B5: SEC | C5: https://www.sec.gov/files/company_tickers.json | D5: Ticker to CIK. XOM mis-resolved to a holding entity; Exxon Mobil Corporation is CIK 0000034088.
A6: Revenue FY2023 | B6: SEC XBRL frames | C6: https://data.sec.gov/api/xbrl/frames/us-gaap/<TAG>/USD/CY2023.json | D6: One call returns every filer. Five tags tried in order: RevenueFromContractWithCustomerExcludingAssessedTax, Revenues, RevenueFromContractWithCustomerIncludingAssessedTax, RevenuesNetOfInterestExpense, SalesRevenueNet. 'Revenues' alone misses most modern filers.
A7: Facility list | B7: EPA GHGRP | C7: https://data.epa.gov/dmapservice/ghg.pub_dim_facility/parent_company/contains/<NAME>/year/equals/2023/0:200/JSON | D7: Searched on a curated parent-name string. 'WALMART' returns nothing; the string is 'WAL-MART'.
A8: Facility emissions | B8: EPA GHGRP | C8: https://data.epa.gov/dmapservice/ghg.pub_facts_sector_ghg_emission/facility_id/in/<IDS>/year/equals/2023/0:300/JSON | D8: Batched 7 facility ids per call because of URL length. Summed across gases per facility.
A9: Ownership share | B9: EPA GHGRP | C9: same facility record, parent_company field | D9: Parsed from the percentage inside the string, e.g. 'NUCOR CORP (51%); YAMATO KOGYO (USA) CORP (49%)'.
A10: Industry factor | B10: EPA | C10: https://pasteur.epa.gov/uploads/10.23719/1531143/SupplyChainGHGEmissionFactors_v1.3.0_NAICS_CO2e_USD2022.csv | D10: 1,016 NAICS-6 commodities. Matched on progressively shorter NAICS prefixes because the table mixes aggregation levels.
A11: Market cap | B11: yfinance | C11: Ticker(...).info['marketCap'] | D11: Optional. Absent here, so the second denominator was unavailable.
A12: GICS sector | B12: manual | C12: companies.csv | D12: Assigned by hand, 10 sectors x 3 companies, so within-sector comparison is possible.
A13: NAICS code | B13: manual | C13: companies.csv | D13: Assigned by hand per company as the expected primary industry, then matched against the EPA table.
